Workbook

Sheet Dashboard
A1: Technical Debt, Risk & Application Portfolio Simulator
A2: Manage technical debt, application risk, and portfolio disposition using the Gartner TIME model.
A3: Edit dropdown options and scoring weights on the Lists sheet. Weights ship at even defaults; calibrated weights are part of the full simulator. See the Instructions tab for how everything works.
A5: ACTIVE DEBT ITEMS | B5: OVERDUE ITEMS | E5: CRITICAL ACTIVE | F5: ACTIVE DIRECT COST
A6: =B37 -> 7 | B6: =B38 -> 6 | E6: =F36 -> 1 | F6: =B53 -> 0
A8: APPLICATIONS | B8: HIGH-RISK APPS | E8: ELIMINATE CANDIDATES | F8: TOTAL ANNUAL RUN COST
A9: =B57 -> 7 | B9: =F58 -> 2 | E9: =B61 -> 1 | F9: =B76 -> 0
A11: Application TIME Matrix (Business Value vs Technical Health)
A12: ="MIGRATE "&COUNTIFS('Application Portfolio'!$B$2:$B$1000,"<>",'Application Portfolio'!$AB$2:$AB$1000,"Migrate")&IF(COUNTIFS('Application Portfolio'!$B$2:$B$1000,"<>",'Application Portfolio'!$AB$2:$AB$1000,"Migrate")=1," app"," apps") -> MIGRATE 3 apps | E12: ="INVEST "&COUNTIFS('Application Portfolio'!$B$2:$B$1000,"<>",'Application Portfolio'!$AB$2:$AB$1000,"Invest")&IF(COUNTIFS('Application Portfolio'!$B$2:$B$1000,"<>",'Application Portfolio'!$AB$2:$AB$1000,"Invest")=1," app"," apps") -> INVEST 2 apps
A13: High business value, low technical health. Modernize or replatform. | E13: High business value, high technical health. Keep investing.
A14: {=IF(COUNTIFS('Application Portfolio'!$B$2:$B$1000,"<>",'Application Portfolio'!$AB$2:$AB$1000,"Migrate")=0,"None",_xlfn.TEXTJOIN(", ",TRUE(),IF(('Application Portfolio'!$AB$2:$AB$1000="Migrate")*('Application Portfolio'!$B$2:$B$1000<>""),'Application Portfolio'!$B$2:$B$1000,"")))} -> Customer Portal, Payment Processor, Financial Reconciliation | E14: {=IF(COUNTIFS('Application Portfolio'!$B$2:$B$1000,"<>",'Application Portfolio'!$AB$2:$AB$1000,"Invest")=0,"None",_xlfn.TEXTJOIN(", ",TRUE(),IF(('Application Portfolio'!$AB$2:$AB$1000="Invest")*('Application Portfolio'!$B$2:$B$1000<>""),'Application Portfolio'!$B$2:$B$1000,"")))} -> Order Management System, Partner API Gateway
A16: ="ELIMINATE "&COUNTIFS('Application Portfolio'!$B$2:$B$1000,"<>",'Application Portfolio'!$AB$2:$AB$1000,"Eliminate")&IF(COUNTIFS('Application Portfolio'!$B$2:$B$1000,"<>",'Application Portfolio'!$AB$2:$AB$1000,"Eliminate")=1," app"," apps") -> ELIMINATE 1 app | E16: ="TOLERATE "&COUNTIFS('Application Portfolio'!$B$2:$B$1000,"<>",'Application Portfolio'!$AB$2:$AB$1000,"Tolerate")&IF(COUNTIFS('Application Portfolio'!$B$2:$B$1000,"<>",'Application Portfolio'!$AB$2:$AB$1000,"Tolerate")=1," app"," apps") -> TOLERATE 1 app
A17: Low business value, low technical health. Retire or consolidate. | E17: Low business value, high technical health. Keep running, minimal spend.
A18: {=IF(COUNTIFS('Application Portfolio'!$B$2:$B$1000,"<>",'Application Portfolio'!$AB$2:$AB$1000,"Eliminate")=0,"None",_xlfn.TEXTJOIN(", ",TRUE(),IF(('Application Portfolio'!$AB$2:$AB$1000="Eliminate")*('Application Portfolio'!$B$2:$B$1000<>""),'Application Portfolio'!$B$2:$B$1000,"")))} -> Legacy CRM | E18: {=IF(COUNTIFS('Application Portfolio'!$B$2:$B$1000,"<>",'Application Portfolio'!$AB$2:$AB$1000,"Tolerate")=0,"None",_xlfn.TEXTJOIN(", ",TRUE(),IF(('Application Portfolio'!$AB$2:$AB$1000="Tolerate")*('Application Portfolio'!$B$2:$B$1000<>""),'Application Portfolio'!$B$2:$B$1000,"")))} -> Marketing Analytics
A35: Debt Backlog - At a Glance | E35: Debt - Active by Severity
A36: Total Items | B36: =COUNTA('Debt Backlog'!B2:B1000) -> 7 | E36: Critical Active | F36: =COUNTIFS('Debt Backlog'!B2:B1000,"<>",'Debt Backlog'!H2:H1000,"Critical",'Debt Backlog'!N2:N1000,"<>Done",'Debt Backlog'!N2:N1000,"<>Won't Fix",'Debt Backlog'!N2:N1000,"<>Duplicate") -> 1
A37: Active Items | B37: =COUNTIFS('Debt Backlog'!B2:B1000,"<>",'Debt Backlog'!N2:N1000,"<>Done",'Debt Backlog'!N2:N1000,"<>Won't Fix",'Debt Backlog'!N2:N1000,"<>Duplicate") -> 7 | E37: High Active | F37: =COUNTIFS('Debt Backlog'!B2:B1000,"<>",'Debt Backlog'!H2:H1000,"High",'Debt Backlog'!N2:N1000,"<>Done",'Debt Backlog'!N2:N1000,"<>Won't Fix",'Debt Backlog'!N2:N1000,"<>Duplicate") -> 3
A38: Overdue Items | B38: =COUNTIF('Debt Backlog'!AE2:AE1000,"Yes") -> 6 | E38: Medium Active | F38: =COUNTIFS('Debt Backlog'!B2:B1000,"<>",'Debt Backlog'!H2:H1000,"Medium",'Debt Backlog'!N2:N1000,"<>Done",'Debt Backlog'!N2:N1000,"<>Won't Fix",'Debt Backlog'!N2:N1000,"<>Duplicate") -> 2
A39: Done Items | B39: =COUNTIFS('Debt Backlog'!B2:B1000,"<>",'Debt Backlog'!N2:N1000,"Done") -> 0 | E39: Low Active | F39: =COUNTIFS('Debt Backlog'!B2:B1000,"<>",'Debt Backlog'!H2:H1000,"Low",'Debt Backlog'!N2:N1000,"<>Done",'Debt Backlog'!N2:N1000,"<>Won't Fix",'Debt Backlog'!N2:N1000,"<>Duplicate") -> 1
A41: Debt Status Breakdown | E41: Severity Breakdown (legend)
A42: Status | B42: Count | E42: Severity | F42: Count
A43: New | B43: =COUNTIFS('Debt Backlog'!B$2:B$1000,"<>",'Debt Backlog'!N$2:N$1000,A43) -> 2 | E43: Critical | F43: =COUNTIFS('Debt Backlog'!B$2:B$1000,"<>",'Debt Backlog'!H$2:H$1000,E43,'Debt Backlog'!N$2:N$1000,"<>Done",'Debt Backlog'!N$2:N$1000,"<>Won't Fix",'Debt Backlog'!N$2:N$1000,"<>Duplicate") -> 1
A44: Triaged | B44: =COUNTIFS('Debt Backlog'!B$2:B$1000,"<>",'Debt Backlog'!N$2:N$1000,A44) -> 1 | E44: High | F44: =COUNTIFS('Debt Backlog'!B$2:B$1000,"<>",'Debt Backlog'!H$2:H$1000,E44,'Debt Backlog'!N$2:N$1000,"<>Done",'Debt Backlog'!N$2:N$1000,"<>Won't Fix",'Debt Backlog'!N$2:N$1000,"<>Duplicate") -> 3
A45: Planned | B45: =COUNTIFS('Debt Backlog'!B$2:B$1000,"<>",'Debt Backlog'!N$2:N$1000,A45) -> 2 | E45: Medium | F45: =COUNTIFS('Debt Backlog'!B$2:B$1000,"<>",'Debt Backlog'!H$2:H$1000,E45,'Debt Backlog'!N$2:N$1000,"<>Done",'Debt Backlog'!N$2:N$1000,"<>Won't Fix",'Debt Backlog'!N$2:N$1000,"<>Duplicate") -> 2
A46: In Progress | B46: =COUNTIFS('Debt Backlog'!B$2:B$1000,"<>",'Debt Backlog'!N$2:N$1000,A46) -> 2 | E46: Low | F46: =COUNTIFS('Debt Backlog'!B$2:B$1000,"<>",'Debt Backlog'!H$2:H$1000,E46,'Debt Backlog'!N$2:N$1000,"<>Done",'Debt Backlog'!N$2:N$1000,"<>Won't Fix",'Debt Backlog'!N$2:N$1000,"<>Duplicate") -> 1
A47: Blocked | B47: =COUNTIFS('Debt Backlog'!B$2:B$1000,"<>",'Debt Backlog'!N$2:N$1000,A47) -> 0
A48: Done | B48: =COUNTIFS('Debt Backlog'!B$2:B$1000,"<>",'Debt Backlog'!N$2:N$1000,A48) -> 0
A49: Won't Fix | B49: =COUNTIFS('Debt Backlog'!B$2:B$1000,"<>",'Debt Backlog'!N$2:N$1000,A49) -> 0
A50: Duplicate | B50: =COUNTIFS('Debt Backlog'!B$2:B$1000,"<>",'Debt Backlog'!N$2:N$1000,A50) -> 0
A52: Debt Cost Summary | E52: Cost by Confidence
A53: Total Direct ($) | B53: =SUMIFS('Debt Backlog'!Y2:Y1000,'Debt Backlog'!B2:B1000,"<>",'Debt Backlog'!N2:N1000,"<>Done",'Debt Backlog'!N2:N1000,"<>Won't Fix",'Debt Backlog'!N2:N1000,"<>Duplicate") -> 0 | E53: High Confidence ($) | F53: =SUMIFS('Debt Backlog'!Y2:Y1000,'Debt Backlog'!B2:B1000,"<>",'Debt Backlog'!AB2:AB1000,"High",'Debt Backlog'!N2:N1000,"<>Done",'Debt Backlog'!N2:N1000,"<>Won't Fix",'Debt Backlog'!N2:N1000,"<>Duplicate") -> 0
A54: Total Annual Carry ($) | B54: =SUMIFS('Debt Backlog'!Z2:Z1000,'Debt Backlog'!B2:B1000,"<>",'Debt Backlog'!N2:N1000,"<>Done",'Debt Backlog'!N2:N1000,"<>Won't Fix",'Debt Backlog'!N2:N1000,"<>Duplicate") -> 0 | E54: Medium Confidence ($) | F54: =SUMIFS('Debt Backlog'!Y2:Y1000,'Debt Backlog'!B2:B1000,"<>",'Debt Backlog'!AB2:AB1000,"Medium",'Debt Backlog'!N2:N1000,"<>Done",'Debt Backlog'!N2:N1000,"<>Won't Fix",'Debt Backlog'!N2:N1000,"<>Duplicate") -> 0
A55: Total Contingent ($) | B55: =SUMIFS('Debt Backlog'!AA2:AA1000,'Debt Backlog'!B2:B1000,"<>",'Debt Backlog'!N2:N1000,"<>Done",'Debt Backlog'!N2:N1000,"<>Won't Fix",'Debt Backlog'!N2:N1000,"<>Duplicate") -> 0 | E55: Low Confidence ($) | F55: =SUMIFS('Debt Backlog'!Y2:Y1000,'Debt Backlog'!B2:B1000,"<>",'Debt Backlog'!AB2:AB1000,"Low",'Debt Backlog'!N2:N1000,"<>Done",'Debt Backlog'!N2:N1000,"<>Won't Fix",'Debt Backlog'!N2:N1000,"<>Duplicate") -> 0
A56: Application Portfolio (APM) - TIME Classification | E56: Portfolio Health Indicators
A57: Total Applications | B57: =COUNTA('Application Portfolio'!B2:B1000) -> 7 | E57: Average CPS | F57: =IFERROR(AVERAGE('Application Portfolio'!AA2:AA1000),"") -> -0.028571429
A58: INVEST | B58: =COUNTIFS('Application Portfolio'!B2:B1000,"<>",'Application Portfolio'!AB2:AB1000,"Invest") -> 2 | E58: High Risk Apps | F58: =COUNTIFS('Application Portfolio'!B2:B1000,"<>",'Application Portfolio'!O2:O1000,">="&Lists!$AG$4) -> 2
A59: TOLERATE | B59: =COUNTIFS('Application Portfolio'!B2:B1000,"<>",'Application Portfolio'!AB2:AB1000,"Tolerate") -> 1 | E59: High Business Value | F59: =COUNTIFS('Application Portfolio'!B2:B1000,"<>",'Application Portfolio'!N2:N1000,">="&Lists!$AG$2) -> 5
A60: MIGRATE | B60: =COUNTIFS('Application Portfolio'!B2:B1000,"<>",'Application Portfolio'!AB2:AB1000,"Migrate") -> 3 | E60: Low Technical Health | F60: =COUNTIFS('Application Portfolio'!B2:B1000,"<>",'Application Portfolio'!Z2:Z1000,"<"&Lists!$AG$3) -> 4
A61: ELIMINATE | B61: =COUNTIFS('Application Portfolio'!B2:B1000,"<>",'Application Portfolio'!AB2:AB1000,"Eliminate") -> 1 | E61: High Cost Apps | F61: =COUNTIFS('Application Portfolio'!B2:B1000,"<>",'Application Portfolio'!T2:T1000,">="&Lists!$AG$6) -> 3
A63: TIME Breakdown | E63: Risk Distribution
...

Sheet Instructions
B1: How to Use This Workbook
B2: What each tab does, how the scores are calculated, and how to change lists, weights and thresholds.
B4: What this workbook does
B5: It keeps three registers in one place: a technical debt backlog, an application risk register, and an application portfolio. It scores every item, classifies each application with the Gartner TIME model (Invest, Tolerate, Migrate, Eliminate), links debt to the applications it sits on, and rolls everything up to the Dashboard. Everything recalculates as you type; there are no macros and nothing to refresh.
B7: The tabs
B8: Dashboard | C8: Read-only. Top: headline tiles (numbers that need attention turn red when above zero), the TIME matrix listing every application in its quadrant, and two charts (portfolio mix and active debt by severity). Below: the detail tables, with in-cell bars, for debt status, severity, cost, TIME, risk, run cost, thresholds, the next ID to assign on each sheet, and data-quality cross-checks. Everything updates on its own.
B9: Instructions | C9: This page.
B10: Debt Backlog | C10: One row per technical debt item. You enter the item; the sheet scores it, sets its priority and due date, flags it overdue, and links it to an application.
B11: Risk Register | C11: One row per application, scored on five risk factors. The Risk Score feeds the Application Portfolio.
B12: Application Portfolio | C12: One row per application, scored on value, cost and technical health. The sheet works out the TIME classification, a composite score, a value vs risk quadrant, and the open debt on each app.
B13: Lists | C13: Every dropdown list, scoring weight, threshold, due-date window and priority cutoff. Change the model here, not in the formulas.
B15: Cell colors
B16: Light blue | C16: Calculated. Do not type in these cells; doing so overwrites the formula for that row.
B17: Pale yellow | C17: Score input, 1 to 5 (Application Portfolio scoring columns).
B18: Light gray / white | C18: Regular input: text, dates, dropdowns and dollar amounts.
B19: Red ID cell | C19: The ID in column A is blank, duplicated or malformed. Fix it before relying on the numbers.
B21: Quick start
B22: 1. Add applications | C22: On Application Portfolio, put the Next App ID from the Dashboard in column A, the name in B, and score the pale-yellow columns 1 to 5. Add Total Annual Cost ($) in column AG if you have it.
B23: 2. Score their risk | C23: On Risk Register, add one row per application: Next Risk ID, pick the App ID, and score the five risk factors 1 to 5. The Risk Score flows back to the portfolio.
B24: 3. Log debt | C24: On Debt Backlog, use the Next Debt ID, enter a Title, then pick Severity, Impact, Confidence and Effort. Those four drive the score. Pick the App ID so the debt rolls up to that application.
B25: 4. Keep it current | C25: Update Status as work moves. Set Date Identified and a Target Window (or a Due Date) so overdue items are flagged. Check the Dashboard cross-checks now and then.
B27: Debt Backlog: how it calculates
B28: Debt Score (L) | C28: Severity points x Impact points x Confidence weight / Effort points, using the tables on Lists. Defaults: Severity Critical 4, High 3, Medium 2, Low 1. Impact High 3, Medium 2, Low 1. Confidence High 1.0, Medium 0.8, Low 0.6. Effort XS 1, S 2, M 3, L 5, XL 8. Bigger, surer, cheaper fixes score higher. Blank until Title, Severity, Impact, Confidence and Effort are all filled.
B29: Priority (M) | C29: Priority Override (AC) wins if you enter one. Otherwise Critical severity is always P0. Otherwise the Debt Score is compared with the cutoffs on Lists AL:AM (defaults P0 at 3.5 or more, P1 at 2.5, P2 at 1.5, anything lower is P3).
B30: Age (R) | C30: Days since Date Identified.
B31: Effective Due Date (AD) | C31: Due Date (T) if you enter one. Otherwise Date Identified plus the days for the Target Window on Lists AI:AJ (Next Sprint 14, Next 2 Sprints 28, This Quarter 90, Next Quarter 180). Backlog and TBD have no implied date.
B32: Overdue (AE) | C32: Yes when the Effective Due Date has passed and the item is still active.
B33: Active | C33: Any status except Done, Won't Fix and Duplicate. Active items drive the Dashboard counts, cost totals and the open debt rollups on the portfolio.
B34: App link (AF:AH) | C34: Pick an App ID and the application name and its TIME classification are pulled in. "Unknown App ID" means the ID is not on Application Portfolio.
B35: Costs (Y:AB) | C35: Direct remediation, annual carry and contingent risk cost, plus how sure you are of the numbers. Active items feed the Debt Cost Summary and Cost by Confidence on the Dashboard.
B37: Risk Register: how it calculates
B38: Risk Score (I) | C38: Weighted average of the five factors (Cybersecurity, Compliance, Operational Resilience, Vendor, Knowledge Concentration) using the Risk weights on Lists. 5 is the riskiest. Blank until all five are scored.
B39: One row per app | C39: The portfolio reads the first row it finds for each App ID. A second row for the same app is ignored and counted under "Apps with more than one risk row" on the Dashboard.
B41: Application Portfolio: how it calculates
B42: Scoring direction | C42: Business Value and Technical Health factors: 5 is best. That includes Integration Complexity and Technical Debt, so score them 5 when complexity or debt is low. Cost factors: 5 is the most expensive. Risk comes from the Risk Register, where 5 is the riskiest.
B43: BV, C, TH (N, T, Z) | C43: Business Value, Cost Score and Technical Health are weighted averages of their 1-5 inputs, using the weights on Lists. Each is blank until every factor in its group is scored.
B44: Risk Score (O) | C44: Pulled from the Risk Register by App ID.
B45: CPS (AA) | C45: Composite Portfolio Score = BV x weight - Risk x weight - Cost x weight + TH x weight. It rewards value and technical health and penalizes risk and cost, in one number. Blank until BV, Risk, Cost and TH all have a score.
B46: CPS range | C46: With the default even weights (0.25 each) CPS runs from -2.00 to +2.00. +2.00 means BV and TH scored 5 with Risk and Cost scored 1. -2.00 is the reverse. 0.00 means value and health exactly offset risk and cost, for example every factor scored 3.
B47: What is a good CPS | C47: Rule of thumb, not a built-in threshold (nothing in the workbook classifies by CPS; the Dashboard only shows the average): +1.0 or higher is strong. 0 to +1.0 is sound, with value and health ahead of risk and cost. -1.0 to 0 is a watch item, where risk and cost outweigh what the app delivers. Below -1.0 is weak and a candidate for remediation or retirement.
...

Sheet Debt Backlog
A1: Debt ID | B1: Title | C1: Description | D1: Product/Service | E1: Component/Module | F1: Debt Type | G1: Impact Area | H1: Severity | I1: Impact | J1: Confidence | K1: Effort | L1: Debt Score | M1: Priority | N1: Status | O1: Owner | P1: Team | Q1: Date Identified | R1: Age (days) | S1: Target Window | T1: Due Date | U1: Last Updated | V1: Dependencies/Related Work | W1: Link (Jira/Confluence/LeanIX) | X1: Notes | Y1: Direct Remediation Cost ($) | Z1: Annual Carry Cost ($) | AA1: Contingent Risk Cost ($) | AB1: Cost Confidence | AC1: Priority Override | AD1: Effective Due Date | AE1: Overdue | AF1: App ID | AG1: Application Name | AH1: App TIME Classification
A2: TD-0001 | B2: Legacy auth library past EOL | C2: Spring Security 4.x, end of life 2022, multiple CVEs unpatched. | D2: Customer Portal | E2: auth-service | F2: Security | G2: Security | H2: Critical | I2: High | J2: High | K2: L | L2: =IF(OR($B2="", $H2="", $I2="", $J2="", $K2=""),"",ROUND((VLOOKUP($H2,Lists!$E$2:$F$5,2,FALSE())*VLOOKUP($I2,Lists!$H$2:$I$4,2,FALSE())*VLOOKUP($J2,Lists!$K$2:$L$4,2,FALSE()))/VLOOKUP($K2,Lists!$N$2:$O$6,2,FALSE()),2)) -> 2.4 | M2: =IF($B2="","",IF($AC2<>"",$AC2,IF($H2="Critical","P0",IF(NOT(ISNUMBER($L2)),"",IF($L2>=Lists!$AM$2,"P0",IF($L2>=Lists!$AM$3,"P1",IF($L2>=Lists!$AM$4,"P2","P3"))))))) -> P0 | N2: In Progress | O2: J. Park | P2: Platform | Q2: 45976 | R2: =IF($Q2="","", TODAY()-$Q2) -> 344 | S2: This Quarter | V2: Coordination with Identity team | W2: JIRA-TD-1041 | X2: Blocks HITRUST certification | AD2: =IF($B2="","",IF(ISNUMBER($T2),$T2,IF(OR(NOT(ISNUMBER($Q2)),$S2=""),"",IFERROR(IF(ISNUMBER(INDEX(Lists!$AJ$2:$AJ$7,MATCH($S2,Lists!$AI$2:$AI$7,0))),$Q2+INDEX(Lists!$AJ$2:$AJ$7,MATCH($S2,Lists!$AI$2:$AI$7,0)),""),"")))) -> 46066 | AE2: =IF($B2="","",IF(AND(ISNUMBER($AD2),N($AD2)<TODAY(),$N2<>"Done",$N2<>"Won't Fix",$N2<>"Duplicate"),"Yes","No")) -> Yes | AF2: APM-0001 | AG2: =IF($AF2="","",IFERROR(VLOOKUP($AF2,'Application Portfolio'!$A$2:$B$1000,2,FALSE()),"Unknown App ID")) -> Customer Portal | AH2: =IF(OR($B2="",$AF2=""),"",IFERROR(VLOOKUP($AF2,'Application Portfolio'!$A$2:$AB$1000,28,FALSE()),"")) -> Migrate
A3: TD-0002 | B3: Orders table missing indexes | C3: Supply order queries degrading as volume grows, p95 over 2s. | D3: Order Management | E3: order-db | F3: Infrastructure | G3: Performance | H3: High | I3: High | J3: High | K3: M | L3: =IF(OR($B3="", $H3="", $I3="", $J3="", $K3=""),"",ROUND((VLOOKUP($H3,Lists!$E$2:$F$5,2,FALSE())*VLOOKUP($I3,Lists!$H$2:$I$4,2,FALSE())*VLOOKUP($J3,Lists!$K$2:$L$4,2,FALSE()))/VLOOKUP($K3,Lists!$N$2:$O$6,2,FALSE()),2)) -> 3 | M3: =IF($B3="","",IF($AC3<>"",$AC3,IF($H3="Critical","P0",IF(NOT(ISNUMBER($L3)),"",IF($L3>=Lists!$AM$2,"P0",IF($L3>=Lists!$AM$3,"P1",IF($L3>=Lists!$AM$4,"P2","P3"))))))) -> P1 | N3: Planned | O3: M. Chen | P3: Data | Q3: 45994 | R3: =IF($Q3="","", TODAY()-$Q3) -> 326 | S3: Next Sprint | V3: None | W3: JIRA-TD-1073 | AD3: =IF($B3="","",IF(ISNUMBER($T3),$T3,IF(OR(NOT(ISNUMBER($Q3)),$S3=""),"",IFERROR(IF(ISNUMBER(INDEX(Lists!$AJ$2:$AJ$7,MATCH($S3,Lists!$AI$2:$AI$7,0))),$Q3+INDEX(Lists!$AJ$2:$AJ$7,MATCH($S3,Lists!$AI$2:$AI$7,0)),""),"")))) -> 46008 | AE3: =IF($B3="","",IF(AND(ISNUMBER($AD3),N($AD3)<TODAY(),$N3<>"Done",$N3<>"Won't Fix",$N3<>"Duplicate"),"Yes","No")) -> Yes | AF3: APM-0002 | AG3: =IF($AF3="","",IFERROR(VLOOKUP($AF3,'Application Portfolio'!$A$2:$B$1000,2,FALSE()),"Unknown App ID")) -> Order Management System | AH3: =IF(OR($B3="",$AF3=""),"",IFERROR(VLOOKUP($AF3,'Application Portfolio'!$A$2:$AB$1000,28,FALSE()),"")) -> Invest
A4: TD-0003 | B4: Hardcoded config in payments | C4: Env values embedded in code, requires redeploy to change. | D4: Payments | E4: payment-processor | F4: Code Quality | G4: Maintainability | H4: High | I4: Medium | J4: High | K4: S | L4: =IF(OR($B4="", $H4="", $I4="", $J4="", $K4=""),"",ROUND((VLOOKUP($H4,Lists!$E$2:$F$5,2,FALSE())*VLOOKUP($I4,Lists!$H$2:$I$4,2,FALSE())*VLOOKUP($J4,Lists!$K$2:$L$4,2,FALSE()))/VLOOKUP($K4,Lists!$N$2:$O$6,2,FALSE()),2)) -> 3 | M4: =IF($B4="","",IF($AC4<>"",$AC4,IF($H4="Critical","P0",IF(NOT(ISNUMBER($L4)),"",IF($L4>=Lists!$AM$2,"P0",IF($L4>=Lists!$AM$3,"P1",IF($L4>=Lists!$AM$4,"P2","P3"))))))) -> P1 | N4: Triaged | O4: R. Singh | P4: Backend | Q4: 46030 | R4: =IF($Q4="","", TODAY()-$Q4) -> 290 | S4: Next 2 Sprints | V4: None | W4: JIRA-TD-1102 | AD4: =IF($B4="","",IF(ISNUMBER($T4),$T4,IF(OR(NOT(ISNUMBER($Q4)),$S4=""),"",IFERROR(IF(ISNUMBER(INDEX(Lists!$AJ$2:$AJ$7,MATCH($S4,Lists!$AI$2:$AI$7,0))),$Q4+INDEX(Lists!$AJ$2:$AJ$7,MATCH($S4,Lists!$AI$2:$AI$7,0)),""),"")))) -> 46058 | AE4: =IF($B4="","",IF(AND(ISNUMBER($AD4),N($AD4)<TODAY(),$N4<>"Done",$N4<>"Won't Fix",$N4<>"Duplicate"),"Yes","No")) -> Yes | AF4: APM-0003 | AG4: =IF($AF4="","",IFERROR(VLOOKUP($AF4,'Application Portfolio'!$A$2:$B$1000,2,FALSE()),"Unknown App ID")) -> Payment Processor | AH4: =IF(OR($B4="",$AF4=""),"",IFERROR(VLOOKUP($AF4,'Application Portfolio'!$A$2:$AB$1000,28,FALSE()),"")) -> Migrate
A5: TD-0004 | B5: No integration tests on billing | C5: Only unit tests, prod-only bugs found monthly. | D5: Billing | E5: billing-svc | F5: Test Coverage | G5: Reliability | H5: Medium | I5: High | J5: Medium | K5: L | L5: =IF(OR($B5="", $H5="", $I5="", $J5="", $K5=""),"",ROUND((VLOOKUP($H5,Lists!$E$2:$F$5,2,FALSE())*VLOOKUP($I5,Lists!$H$2:$I$4,2,FALSE())*VLOOKUP($J5,Lists!$K$2:$L$4,2,FALSE()))/VLOOKUP($K5,Lists!$N$2:$O$6,2,FALSE()),2)) -> 0.96 | M5: =IF($B5="","",IF($AC5<>"",$AC5,IF($H5="Critical","P0",IF(NOT(ISNUMBER($L5)),"",IF($L5>=Lists!$AM$2,"P0",IF($L5>=Lists!$AM$3,"P1",IF($L5>=Lists!$AM$4,"P2","P3"))))))) -> P3 | N5: New | P5: QA | Q5: 46065 | R5: =IF($Q5="","", TODAY()-$Q5) -> 255 | S5: Next Quarter | V5: Test data framework | X5: Owner TBD | AD5: =IF($B5="","",IF(ISNUMBER($T5),$T5,IF(OR(NOT(ISNUMBER($Q5)),$S5=""),"",IFERROR(IF(ISNUMBER(INDEX(Lists!$AJ$2:$AJ$7,MATCH($S5,Lists!$AI$2:$AI$7,0))),$Q5+INDEX(Lists!$AJ$2:$AJ$7,MATCH($S5,Lists!$AI$2:$AI$7,0)),""),"")))) -> 46245 | AE5: =IF($B5="","",IF(AND(ISNUMBER($AD5),N($AD5)<TODAY(),$N5<>"Done",$N5<>"Won't Fix",$N5<>"Duplicate"),"Yes","No")) -> Yes | AG5: =IF($AF5="","",IFERROR(VLOOKUP($AF5,'Application Portfolio'!$A$2:$B$1000,2,FALSE()),"Unknown App ID")) | AH5: =IF(OR($B5="",$AF5=""),"",IFERROR(VLOOKUP($AF5,'Application Portfolio'!$A$2:$AB$1000,28,FALSE()),""))
A6: TD-0005 | B6: React version 3 majors behind | C6: v16 in use, ecosystem moving to v19. | D6: Customer Portal | E6: web-ui | F6: Dependencies/Upgrades | G6: Developer Productivity | H6: Medium | I6: Medium | J6: High | K6: M | L6: =IF(OR($B6="", $H6="", $I6="", $J6="", $K6=""),"",ROUND((VLOOKUP($H6,Lists!$E$2:$F$5,2,FALSE())*VLOOKUP($I6,Lists!$H$2:$I$4,2,FALSE())*VLOOKUP($J6,Lists!$K$2:$L$4,2,FALSE()))/VLOOKUP($K6,Lists!$N$2:$O$6,2,FALSE()),2)) -> 1.33 | M6: =IF($B6="","",IF($AC6<>"",$AC6,IF($H6="Critical","P0",IF(NOT(ISNUMBER($L6)),"",IF($L6>=Lists!$AM$2,"P0",IF($L6>=Lists!$AM$3,"P1",IF($L6>=Lists!$AM$4,"P2","P3"))))))) -> P3 | N6: Planned | O6: L. Ramirez | P6: Frontend | Q6: 45952 | R6: =IF($Q6="","", TODAY()-$Q6) -> 368 | S6: Next Quarter | V6: Design system rework | W6: JIRA-TD-0994 | AD6: =IF($B6="","",IF(ISNUMBER($T6),$T6,IF(OR(NOT(ISNUMBER($Q6)),$S6=""),"",IFERROR(IF(ISNUMBER(INDEX(Lists!$AJ$2:$AJ$7,MATCH($S6,Lists!$AI$2:$AI$7,0))),$Q6+INDEX(Lists!$AJ$2:$AJ$7,MATCH($S6,Lists!$AI$2:$AI$7,0)),""),"")))) -> 46132 | AE6: =IF($B6="","",IF(AND(ISNUMBER($AD6),N($AD6)<TODAY(),$N6<>"Done",$N6<>"Won't Fix",$N6<>"Duplicate"),"Yes","No")) -> Yes | AF6: APM-0001 | AG6: =IF($AF6="","",IFERROR(VLOOKUP($AF6,'Application Portfolio'!$A$2:$B$1000,2,FALSE()),"Unknown App ID")) -> Customer Portal | AH6: =IF(OR($B6="",$AF6=""),"",IFERROR(VLOOKUP($AF6,'Application Portfolio'!$A$2:$AB$1000,28,FALSE()),"")) -> Migrate
A7: TD-0006 | B7: Observability gaps on batch jobs | C7: Nightly reconciliation has no alerting, failures found by users. | D7: Finance Ops | E7: recon-batch | F7: Observability | G7: Reliability | H7: High | I7: High | J7: Medium | K7: S | L7: =IF(OR($B7="", $H7="", $I7="", $J7="", $K7=""),"",ROUND((VLOOKUP($H7,Lists!$E$2:$F$5,2,FALSE())*VLOOKUP($I7,Lists!$H$2:$I$4,2,FALSE())*VLOOKUP($J7,Lists!$K$2:$L$4,2,FALSE()))/VLOOKUP($K7,Lists!$N$2:$O$6,2,FALSE()),2)) -> 3.6 | M7: =IF($B7="","",IF($AC7<>"",$AC7,IF($H7="Critical","P0",IF(NOT(ISNUMBER($L7)),"",IF($L7>=Lists!$AM$2,"P0",IF($L7>=Lists!$AM$3,"P1",IF($L7>=Lists!$AM$4,"P2","P3"))))))) -> P0 | N7: In Progress | O7: K. Osei | P7: DevOps | Q7: 46009 | R7: =IF($Q7="","", TODAY()-$Q7) -> 311 | S7: Next Sprint | V7: Grafana dashboards | W7: JIRA-TD-1128 | AD7: =IF($B7="","",IF(ISNUMBER($T7),$T7,IF(OR(NOT(ISNUMBER($Q7)),$S7=""),"",IFERROR(IF(ISNUMBER(INDEX(Lists!$AJ$2:$AJ$7,MATCH($S7,Lists!$AI$2:$AI$7,0))),$Q7+INDEX(Lists!$AJ$2:$AJ$7,MATCH($S7,Lists!$AI$2:$AI$7,0)),""),"")))) -> 46023 | AE7: =IF($B7="","",IF(AND(ISNUMBER($AD7),N($AD7)<TODAY(),$N7<>"Done",$N7<>"Won't Fix",$N7<>"Duplicate"),"Yes","No")) -> Yes | AF7: APM-0006 | AG7: =IF($AF7="","",IFERROR(VLOOKUP($AF7,'Application Portfolio'!$A$2:$B$1000,2,FALSE()),"Unknown App ID")) -> Financial Reconciliation | AH7: =IF(OR($B7="",$AF7=""),"",IFERROR(VLOOKUP($AF7,'Application Portfolio'!$A$2:$AB$1000,28,FALSE()),"")) -> Migrate
A8: TD-0007 | B8: Outdated API docs | C8: Swagger and FHIR capability statement not regenerated in 18 months; payer and lab integrations slowed. | D8: Partner API | E8: api-gateway | F8: Documentation | G8: Developer Productivity | H8: Low | I8: Medium | J8: High | K8: XS | L8: =IF(OR($B8="", $H8="", $I8="", $J8="", $K8=""),"",ROUND((VLOOKUP($H8,Lists!$E$2:$F$5,2,FALSE())*VLOOKUP($I8,Lists!$H$2:$I$4,2,FALSE())*VLOOKUP($J8,Lists!$K$2:$L$4,2,FALSE()))/VLOOKUP($K8,Lists!$N$2:$O$6,2,FALSE()),2)) -> 2 | M8: =IF($B8="","",IF($AC8<>"",$AC8,IF($H8="Critical","P0",IF(NOT(ISNUMBER($L8)),"",IF($L8>=Lists!$AM$2,"P0",IF($L8>=Lists!$AM$3,"P1",IF($L8>=Lists!$AM$4,"P2","P3"))))))) -> P2 | N8: New | O8: T. Morgan | P8: Backend | Q8: 46086 | R8: =IF($Q8="","", TODAY()-$Q8) -> 234 | S8: Backlog | V8: None | AD8: =IF($B8="","",IF(ISNUMBER($T8),$T8,IF(OR(NOT(ISNUMBER($Q8)),$S8=""),"",IFERROR(IF(ISNUMBER(INDEX(Lists!$AJ$2:$AJ$7,MATCH($S8,Lists!$AI$2:$AI$7,0))),$Q8+INDEX(Lists!$AJ$2:$AJ$7,MATCH($S8,Lists!$AI$2:$AI$7,0)),""),"")))) | AE8: =IF($B8="","",IF(AND(ISNUMBER($AD8),N($AD8)<TODAY(),$N8<>"Done",$N8<>"Won't Fix",$N8<>"Duplicate"),"Yes","No")) -> No | AF8: APM-0007 | AG8: =IF($AF8="","",IFERROR(VLOOKUP($AF8,'Application Portfolio'!$A$2:$B$1000,2,FALSE()),"Unknown App ID")) -> Partner API Gateway | AH8: =IF(OR($B8="",$AF8=""),"",IFERROR(VLOOKUP($AF8,'Application Portfolio'!$A$2:$AB$1000,28,FALSE()),"")) -> Invest
L9: =IF(OR($B9="", $H9="", $I9="", $J9="", $K9=""),"",ROUND((VLOOKUP($H9,Lists!$E$2:$F$5,2,FALSE())*VLOOKUP($I9,Lists!$H$2:$I$4,2,FALSE())*VLOOKUP($J9,Lists!$K$2:$L$4,2,FALSE()))/VLOOKUP($K9,Lists!$N$2:$O$6,2,FALSE()),2)) | M9: =IF($B9="","",IF($AC9<>"",$AC9,IF($H9="Critical","P0",IF(NOT(ISNUMBER($L9)),"",IF($L9>=Lists!$AM$2,"P0",IF($L9>=Lists!$AM$3,"P1",IF($L9>=Lists!$AM$4,"P2","P3"))))))) | R9: =IF($Q9="","", TODAY()-$Q9) | AD9: =IF($B9="","",IF(ISNUMBER($T9),$T9,IF(OR(NOT(ISNUMBER($Q9)),$S9=""),"",IFERROR(IF(ISNUMBER(INDEX(Lists!$AJ$2:$AJ$7,MATCH($S9,Lists!$AI$2:$AI$7,0))),$Q9+INDEX(Lists!$AJ$2:$AJ$7,MATCH($S9,Lists!$AI$2:$AI$7,0)),""),"")))) | AE9: =IF($B9="","",IF(AND(ISNUMBER($AD9),N($AD9)<TODAY(),$N9<>"Done",$N9<>"Won't Fix",$N9<>"Duplicate"),"Yes","No")) | AG9: =IF($AF9="","",IFERROR(VLOOKUP($AF9,'Application Portfolio'!$A$2:$B$1000,2,FALSE()),"Unknown App ID")) | AH9: =IF(OR($B9="",$AF9=""),"",IFERROR(VLOOKUP($AF9,'Application Portfolio'!$A$2:$AB$1000,28,FALSE()),""))
L10: =IF(OR($B10="", $H10="", $I10="", $J10="", $K10=""),"",ROUND((VLOOKUP($H10,Lists!$E$2:$F$5,2,FALSE())*VLOOKUP($I10,Lists!$H$2:$I$4,2,FALSE())*VLOOKUP($J10,Lists!$K$2:$L$4,2,FALSE()))/VLOOKUP($K10,Lists!$N$2:$O$6,2,FALSE()),2)) | M10: =IF($B10="","",IF($AC10<>"",$AC10,IF($H10="Critical","P0",IF(NOT(ISNUMBER($L10)),"",IF($L10>=Lists!$AM$2,"P0",IF($L10>=Lists!$AM$3,"P1",IF($L10>=Lists!$AM$4,"P2","P3"))))))) | R10: =IF($Q10="","", TODAY()-$Q10) | AD10: =IF($B10="","",IF(ISNUMBER($T10),$T10,IF(OR(NOT(ISNUMBER($Q10)),$S10=""),"",IFERROR(IF(ISNUMBER(INDEX(Lists!$AJ$2:$AJ$7,MATCH($S10,Lists!$AI$2:$AI$7,0))),$Q10+INDEX(Lists!$AJ$2:$AJ$7,MATCH($S10,Lists!$AI$2:$AI$7,0)),""),"")))) | AE10: =IF($B10="","",IF(AND(ISNUMBER($AD10),N($AD10)<TODAY(),$N10<>"Done",$N10<>"Won't Fix",$N10<>"Duplicate"),"Yes","No")) | AG10: =IF($AF10="","",IFERROR(VLOOKUP($AF10,'Application Portfolio'!$A$2:$B$1000,2,FALSE()),"Unknown App ID")) | AH10: =IF(OR($B10="",$AF10=""),"",IFERROR(VLOOKUP($AF10,'Application Portfolio'!$A$2:$AB$1000,28,FALSE()),""))
L11: =IF(OR($B11="", $H11="", $I11="", $J11="", $K11=""),"",ROUND((VLOOKUP($H11,Lists!$E$2:$F$5,2,FALSE())*VLOOKUP($I11,Lists!$H$2:$I$4,2,FALSE())*VLOOKUP($J11,Lists!$K$2:$L$4,2,FALSE()))/VLOOKUP($K11,Lists!$N$2:$O$6,2,FALSE()),2)) | M11: =IF($B11="","",IF($AC11<>"",$AC11,IF($H11="Critical","P0",IF(NOT(ISNUMBER($L11)),"",IF($L11>=Lists!$AM$2,"P0",IF($L11>=Lists!$AM$3,"P1",IF($L11>=Lists!$AM$4,"P2","P3"))))))) | R11: =IF($Q11="","", TODAY()-$Q11) | AD11: =IF($B11="","",IF(ISNUMBER($T11),$T11,IF(OR(NOT(ISNUMBER($Q11)),$S11=""),"",IFERROR(IF(ISNUMBER(INDEX(Lists!$AJ$2:$AJ$7,MATCH($S11,Lists!$AI$2:$AI$7,0))),$Q11+INDEX(Lists!$AJ$2:$AJ$7,MATCH($S11,Lists!$AI$2:$AI$7,0)),""),"")))) | AE11: =IF($B11="","",IF(AND(ISNUMBER($AD11),N($AD11)<TODAY(),$N11<>"Done",$N11<>"Won't Fix",$N11<>"Duplicate"),"Yes","No")) | AG11: =IF($AF11="","",IFERROR(VLOOKUP($AF11,'Application Portfolio'!$A$2:$B$1000,2,FALSE()),"Unknown App ID")) | AH11: =IF(OR($B11="",$AF11=""),"",IFERROR(VLOOKUP($AF11,'Application Portfolio'!$A$2:$AB$1000,28,FALSE()),""))
L12: =IF(OR($B12="", $H12="", $I12="", $J12="", $K12=""),"",ROUND((VLOOKUP($H12,Lists!$E$2:$F$5,2,FALSE())*VLOOKUP($I12,Lists!$H$2:$I$4,2,FALSE())*VLOOKUP($J12,Lists!$K$2:$L$4,2,FALSE()))/VLOOKUP($K12,Lists!$N$2:$O$6,2,FALSE()),2)) | M12: =IF($B12="","",IF($AC12<>"",$AC12,IF($H12="Critical","P0",IF(NOT(ISNUMBER($L12)),"",IF($L12>=Lists!$AM$2,"P0",IF($L12>=Lists!$AM$3,"P1",IF($L12>=Lists!$AM$4,"P2","P3"))))))) | R12: =IF($Q12="","", TODAY()-$Q12) | AD12: =IF($B12="","",IF(ISNUMBER($T12),$T12,IF(OR(NOT(ISNUMBER($Q12)),$S12=""),"",IFERROR(IF(ISNUMBER(INDEX(Lists!$AJ$2:$AJ$7,MATCH($S12,Lists!$AI$2:$AI$7,0))),$Q12+INDEX(Lists!$AJ$2:$AJ$7,MATCH($S12,Lists!$AI$2:$AI$7,0)),""),"")))) | AE12: =IF($B12="","",IF(AND(ISNUMBER($AD12),N($AD12)<TODAY(),$N12<>"Done",$N12<>"Won't Fix",$N12<>"Duplicate"),"Yes","No")) | AG12: =IF($AF12="","",IFERROR(VLOOKUP($AF12,'Application Portfolio'!$A$2:$B$1000,2,FALSE()),"Unknown App ID")) | AH12: =IF(OR($B12="",$AF12=""),"",IFERROR(VLOOKUP($AF12,'Application Portfolio'!$A$2:$AB$1000,28,FALSE()),""))
L13: =IF(OR($B13="", $H13="", $I13="", $J13="", $K13=""),"",ROUND((VLOOKUP($H13,Lists!$E$2:$F$5,2,FALSE())*VLOOKUP($I13,Lists!$H$2:$I$4,2,FALSE())*VLOOKUP($J13,Lists!$K$2:$L$4,2,FALSE()))/VLOOKUP($K13,Lists!$N$2:$O$6,2,FALSE()),2)) | M13: =IF($B13="","",IF($AC13<>"",$AC13,IF($H13="Critical","P0",IF(NOT(ISNUMBER($L13)),"",IF($L13>=Lists!$AM$2,"P0",IF($L13>=Lists!$AM$3,"P1",IF($L13>=Lists!$AM$4,"P2","P3"))))))) | R13: =IF($Q13="","", TODAY()-$Q13) | AD13: =IF($B13="","",IF(ISNUMBER($T13),$T13,IF(OR(NOT(ISNUMBER($Q13)),$S13=""),"",IFERROR(IF(ISNUMBER(INDEX(Lists!$AJ$2:$AJ$7,MATCH($S13,Lists!$AI$2:$AI$7,0))),$Q13+INDEX(Lists!$AJ$2:$AJ$7,MATCH($S13,Lists!$AI$2:$AI$7,0)),""),"")))) | AE13: =IF($B13="","",IF(AND(ISNUMBER($AD13),N($AD13)<TODAY(),$N13<>"Done",$N13<>"Won't Fix",$N13<>"Duplicate"),"Yes","No")) | AG13: =IF($AF13="","",IFERROR(VLOOKUP($AF13,'Application Portfolio'!$A$2:$B$1000,2,FALSE()),"Unknown App ID")) | AH13: =IF(OR($B13="",$AF13=""),"",IFERROR(VLOOKUP($AF13,'Application Portfolio'!$A$2:$AB$1000,28,FALSE()),""))
L14: =IF(OR($B14="", $H14="", $I14="", $J14="", $K14=""),"",ROUND((VLOOKUP($H14,Lists!$E$2:$F$5,2,FALSE())*VLOOKUP($I14,Lists!$H$2:$I$4,2,FALSE())*VLOOKUP($J14,Lists!$K$2:$L$4,2,FALSE()))/VLOOKUP($K14,Lists!$N$2:$O$6,2,FALSE()),2)) | M14: =IF($B14="","",IF($AC14<>"",$AC14,IF($H14="Critical","P0",IF(NOT(ISNUMBER($L14)),"",IF($L14>=Lists!$AM$2,"P0",IF($L14>=Lists!$AM$3,"P1",IF($L14>=Lists!$AM$4,"P2","P3"))))))) | R14: =IF($Q14="","", TODAY()-$Q14) | AD14: =IF($B14="","",IF(ISNUMBER($T14),$T14,IF(OR(NOT(ISNUMBER($Q14)),$S14=""),"",IFERROR(IF(ISNUMBER(INDEX(Lists!$AJ$2:$AJ$7,MATCH($S14,Lists!$AI$2:$AI$7,0))),$Q14+INDEX(Lists!$AJ$2:$AJ$7,MATCH($S14,Lists!$AI$2:$AI$7,0)),""),"")))) | AE14: =IF($B14="","",IF(AND(ISNUMBER($AD14),N($AD14)<TODAY(),$N14<>"Done",$N14<>"Won't Fix",$N14<>"Duplicate"),"Yes","No")) | AG14: =IF($AF14="","",IFERROR(VLOOKUP($AF14,'Application Portfolio'!$A$2:$B$1000,2,FALSE()),"Unknown App ID")) | AH14: =IF(OR($B14="",$AF14=""),"",IFERROR(VLOOKUP($AF14,'Application Portfolio'!$A$2:$AB$1000,28,FALSE()),""))
L15: =IF(OR($B15="", $H15="", $I15="", $J15="", $K15=""),"",ROUND((VLOOKUP($H15,Lists!$E$2:$F$5,2,FALSE())*VLOOKUP($I15,Lists!$H$2:$I$4,2,FALSE())*VLOOKUP($J15,Lists!$K$2:$L$4,2,FALSE()))/VLOOKUP($K15,Lists!$N$2:$O$6,2,FALSE()),2)) | M15: =IF($B15="","",IF($AC15<>"",$AC15,IF($H15="Critical","P0",IF(NOT(ISNUMBER($L15)),"",IF($L15>=Lists!$AM$2,"P0",IF($L15>=Lists!$AM$3,"P1",IF($L15>=Lists!$AM$4,"P2","P3"))))))) | R15: =IF($Q15="","", TODAY()-$Q15) | AD15: =IF($B15="","",IF(ISNUMBER($T15),$T15,IF(OR(NOT(ISNUMBER($Q15)),$S15=""),"",IFERROR(IF(ISNUMBER(INDEX(Lists!$AJ$2:$AJ$7,MATCH($S15,Lists!$AI$2:$AI$7,0))),$Q15+INDEX(Lists!$AJ$2:$AJ$7,MATCH($S15,Lists!$AI$2:$AI$7,0)),""),"")))) | AE15: =IF($B15="","",IF(AND(ISNUMBER($AD15),N($AD15)<TODAY(),$N15<>"Done",$N15<>"Won't Fix",$N15<>"Duplicate"),"Yes","No")) | AG15: =IF($AF15="","",IFERROR(VLOOKUP($AF15,'Application Portfolio'!$A$2:$B$1000,2,FALSE()),"Unknown App ID")) | AH15: =IF(OR($B15="",$AF15=""),"",IFERROR(VLOOKUP($AF15,'Application Portfolio'!$A$2:$AB$1000,28,FALSE()),""))
L16: =IF(OR($B16="", $H16="", $I16="", $J16="", $K16=""),"",ROUND((VLOOKUP($H16,Lists!$E$2:$F$5,2,FALSE())*VLOOKUP($I16,Lists!$H$2:$I$4,2,FALSE())*VLOOKUP($J16,Lists!$K$2:$L$4,2,FALSE()))/VLOOKUP($K16,Lists!$N$2:$O$6,2,FALSE()),2)) | M16: =IF($B16="","",IF($AC16<>"",$AC16,IF($H16="Critical","P0",IF(NOT(ISNUMBER($L16)),"",IF($L16>=Lists!$AM$2,"P0",IF($L16>=Lists!$AM$3,"P1",IF($L16>=Lists!$AM$4,"P2","P3"))))))) | R16: =IF($Q16="","", TODAY()-$Q16) | AD16: =IF($B16="","",IF(ISNUMBER($T16),$T16,IF(OR(NOT(ISNUMBER($Q16)),$S16=""),"",IFERROR(IF(ISNUMBER(INDEX(Lists!$AJ$2:$AJ$7,MATCH($S16,Lists!$AI$2:$AI$7,0))),$Q16+INDEX(Lists!$AJ$2:$AJ$7,MATCH($S16,Lists!$AI$2:$AI$7,0)),""),"")))) | AE16: =IF($B16="","",IF(AND(ISNUMBER($AD16),N($AD16)<TODAY(),$N16<>"Done",$N16<>"Won't Fix",$N16<>"Duplicate"),"Yes","No")) | AG16: =IF($AF16="","",IFERROR(VLOOKUP($AF16,'Application Portfolio'!$A$2:$B$1000,2,FALSE()),"Unknown App ID")) | AH16: =IF(OR($B16="",$AF16=""),"",IFERROR(VLOOKUP($AF16,'Application Portfolio'!$A$2:$AB$1000,28,FALSE()),""))
L17: =IF(OR($B17="", $H17="", $I17="", $J17="", $K17=""),"",ROUND((VLOOKUP($H17,Lists!$E$2:$F$5,2,FALSE())*VLOOKUP($I17,Lists!$H$2:$I$4,2,FALSE())*VLOOKUP($J17,Lists!$K$2:$L$4,2,FALSE()))/VLOOKUP($K17,Lists!$N$2:$O$6,2,FALSE()),2)) | M17: =IF($B17="","",IF($AC17<>"",$AC17,IF($H17="Critical","P0",IF(NOT(ISNUMBER($L17)),"",IF($L17>=Lists!$AM$2,"P0",IF($L17>=Lists!$AM$3,"P1",IF($L17>=Lists!$AM$4,"P2","P3"))))))) | R17: =IF($Q17="","", TODAY()-$Q17) | AD17: =IF($B17="","",IF(ISNUMBER($T17),$T17,IF(OR(NOT(ISNUMBER($Q17)),$S17=""),"",IFERROR(IF(ISNUMBER(INDEX(Lists!$AJ$2:$AJ$7,MATCH($S17,Lists!$AI$2:$AI$7,0))),$Q17+INDEX(Lists!$AJ$2:$AJ$7,MATCH($S17,Lists!$AI$2:$AI$7,0)),""),"")))) | AE17: =IF($B17="","",IF(AND(ISNUMBER($AD17),N($AD17)<TODAY(),$N17<>"Done",$N17<>"Won't Fix",$N17<>"Duplicate"),"Yes","No")) | AG17: =IF($AF17="","",IFERROR(VLOOKUP($AF17,'Application Portfolio'!$A$2:$B$1000,2,FALSE()),"Unknown App ID")) | AH17: =IF(OR($B17="",$AF17=""),"",IFERROR(VLOOKUP($AF17,'Application Portfolio'!$A$2:$AB$1000,28,FALSE()),""))
L18: =IF(OR($B18="", $H18="", $I18="", $J18="", $K18=""),"",ROUND((VLOOKUP($H18,Lists!$E$2:$F$5,2,FALSE())*VLOOKUP($I18,Lists!$H$2:$I$4,2,FALSE())*VLOOKUP($J18,Lists!$K$2:$L$4,2,FALSE()))/VLOOKUP($K18,Lists!$N$2:$O$6,2,FALSE()),2)) | M18: =IF($B18="","",IF($AC18<>"",$AC18,IF($H18="Critical","P0",IF(NOT(ISNUMBER($L18)),"",IF($L18>=Lists!$AM$2,"P0",IF($L18>=Lists!$AM$3,"P1",IF($L18>=Lists!$AM$4,"P2","P3"))))))) | R18: =IF($Q18="","", TODAY()-$Q18) | AD18: =IF($B18="","",IF(ISNUMBER($T18),$T18,IF(OR(NOT(ISNUMBER($Q18)),$S18=""),"",IFERROR(IF(ISNUMBER(INDEX(Lists!$AJ$2:$AJ$7,MATCH($S18,Lists!$AI$2:$AI$7,0))),$Q18+INDEX(Lists!$AJ$2:$AJ$7,MATCH($S18,Lists!$AI$2:$AI$7,0)),""),"")))) | AE18: =IF($B18="","",IF(AND(ISNUMBER($AD18),N($AD18)<TODAY(),$N18<>"Done",$N18<>"Won't Fix",$N18<>"Duplicate"),"Yes","No")) | AG18: =IF($AF18="","",IFERROR(VLOOKUP($AF18,'Application Portfolio'!$A$2:$B$1000,2,FALSE()),"Unknown App ID")) | AH18: =IF(OR($B18="",$AF18=""),"",IFERROR(VLOOKUP($AF18,'Application Portfolio'!$A$2:$AB$1000,28,FALSE()),""))
L19: =IF(OR($B19="", $H19="", $I19="", $J19="", $K19=""),"",ROUND((VLOOKUP($H19,Lists!$E$2:$F$5,2,FALSE())*VLOOKUP($I19,Lists!$H$2:$I$4,2,FALSE())*VLOOKUP($J19,Lists!$K$2:$L$4,2,FALSE()))/VLOOKUP($K19,Lists!$N$2:$O$6,2,FALSE()),2)) | M19: =IF($B19="","",IF($AC19<>"",$AC19,IF($H19="Critical","P0",IF(NOT(ISNUMBER($L19)),"",IF($L19>=Lists!$AM$2,"P0",IF($L19>=Lists!$AM$3,"P1",IF($L19>=Lists!$AM$4,"P2","P3"))))))) | R19: =IF($Q19="","", TODAY()-$Q19) | AD19: =IF($B19="","",IF(ISNUMBER($T19),$T19,IF(OR(NOT(ISNUMBER($Q19)),$S19=""),"",IFERROR(IF(ISNUMBER(INDEX(Lists!$AJ$2:$AJ$7,MATCH($S19,Lists!$AI$2:$AI$7,0))),$Q19+INDEX(Lists!$AJ$2:$AJ$7,MATCH($S19,Lists!$AI$2:$AI$7,0)),""),"")))) | AE19: =IF($B19="","",IF(AND(ISNUMBER($AD19),N($AD19)<TODAY(),$N19<>"Done",$N19<>"Won't Fix",$N19<>"Duplicate"),"Yes","No")) | AG19: =IF($AF19="","",IFERROR(VLOOKUP($AF19,'Application Portfolio'!$A$2:$B$1000,2,FALSE()),"Unknown App ID")) | AH19: =IF(OR($B19="",$AF19=""),"",IFERROR(VLOOKUP($AF19,'Application Portfolio'!$A$2:$AB$1000,28,FALSE()),""))
L20: =IF(OR($B20="", $H20="", $I20="", $J20="", $K20=""),"",ROUND((VLOOKUP($H20,Lists!$E$2:$F$5,2,FALSE())*VLOOKUP($I20,Lists!$H$2:$I$4,2,FALSE())*VLOOKUP($J20,Lists!$K$2:$L$4,2,FALSE()))/VLOOKUP($K20,Lists!$N$2:$O$6,2,FALSE()),2)) | M20: =IF($B20="","",IF($AC20<>"",$AC20,IF($H20="Critical","P0",IF(NOT(ISNUMBER($L20)),"",IF($L20>=Lists!$AM$2,"P0",IF($L20>=Lists!$AM$3,"P1",IF($L20>=Lists!$AM$4,"P2","P3"))))))) | R20: =IF($Q20="","", TODAY()-$Q20) | AD20: =IF($B20="","",IF(ISNUMBER($T20),$T20,IF(OR(NOT(ISNUMBER($Q20)),$S20=""),"",IFERROR(IF(ISNUMBER(INDEX(Lists!$AJ$2:$AJ$7,MATCH($S20,Lists!$AI$2:$AI$7,0))),$Q20+INDEX(Lists!$AJ$2:$AJ$7,MATCH($S20,Lists!$AI$2:$AI$7,0)),""),"")))) | AE20: =IF($B20="","",IF(AND(ISNUMBER($AD20),N($AD20)<TODAY(),$N20<>"Done",$N20<>"Won't Fix",$N20<>"Duplicate"),"Yes","No")) | AG20: =IF($AF20="","",IFERROR(VLOOKUP($AF20,'Application Portfolio'!$A$2:$B$1000,2,FALSE()),"Unknown App ID")) | AH20: =IF(OR($B20="",$AF20=""),"",IFERROR(VLOOKUP($AF20,'Application Portfolio'!$A$2:$AB$1000,28,FALSE()),""))
... L1000: =IF(OR($B1000="", $H1000="", $I1000="", $J1000="", $K1000=""),"",ROUND((VLOOKUP($H1000,Lists!$E$2:$F$5,2,FALSE())*VLOOKUP($I1000,Lists!$H$2:$I$4,2,FALSE())*VLOOKUP($J1000,Lists!$K$2:$L$4,2,FALSE()))/VLOOKUP($K1000,Lists!$N$2:$O$6,2,FALSE()),2)) | M1000: =IF($B1000="","",IF($AC1000<>"",$AC1000,IF($H1000="Critical","P0",IF(NOT(ISNUMBER($L1000)),"",IF($L1000>=Lists!$AM$2,"P0",IF($L1000>=Lists!$AM$3,"P1",IF($L1000>=Lists!$AM$4,"P2","P3"))))))) | R1000: =IF($Q1000="","", TODAY()-$Q1000) | AD1000: =IF($B1000="","",IF(ISNUMBER($T1000),$T1000,IF(OR(NOT(ISNUMBER($Q1000)),$S1000=""),"",IFERROR(IF(ISNUMBER(INDEX(Lists!$AJ$2:$AJ$7,MATCH($S1000,Lists!$AI$2:$AI$7,0))),$Q1000+INDEX(Lists!$AJ$2:$AJ$7,MATCH($S1000,Lists!$AI$2:$AI$7,0)),""),"")))) | AE1000: =IF($B1000="","",IF(AND(ISNUMBER($AD1000),N($AD1000)<TODAY(),$N1000<>"Done",$N1000<>"Won't Fix",$N1000<>"Duplicate"),"Yes","No")) | AG1000: =IF($AF1000="","",IFERROR(VLOOKUP($AF1000,'Application Portfolio'!$A$2:$B$1000,2,FALSE()),"Unknown App ID")) | AH1000: =IF(OR($B1000="",$AF1000=""),"",IFERROR(VLOOKUP($AF1000,'Application Portfolio'!$A$2:$AB$1000,28,FALSE()),""))

Sheet Risk Register
A1: Risk ID | B1: App ID | C1: Application Name | D1: Cybersecurity Risk (1-5) | E1: Compliance Risk (1-5) | F1: Operational Resilience (1-5) | G1: Vendor Risk (1-5) | H1: Knowledge Concentration (1-5) | I1: Risk Score (R) | J1: Owner | K1: Last Updated | L1: Notes
A2: R-0001 | B2: APM-0001 | C2: =IF($B2="","",IFERROR(VLOOKUP($B2,'Application Portfolio'!$A$2:$B$1000,2,FALSE()),"")) -> Customer Portal | D2: 5 | E2: 4 | F2: 3 | G2: 2 | H2: 3 | I2: =IF(OR($B2="", $D2="", $E2="", $F2="", $G2="", $H2=""),"",ROUND(($D2*Lists!$AD$20)+($E2*Lists!$AD$21)+($F2*Lists!$AD$22)+($G2*Lists!$AD$23)+($H2*Lists!$AD$24),2)) -> 3.4 | J2: Security Office | K2: 46127 | L2: High cyber risk due to exposed auth paths
A3: R-0002 | B3: APM-0002 | C3: =IF($B3="","",IFERROR(VLOOKUP($B3,'Application Portfolio'!$A$2:$B$1000,2,FALSE()),"")) -> Order Management System | D3: 2 | E3: 2 | F3: 3 | G3: 2 | H3: 2 | I3: =IF(OR($B3="", $D3="", $E3="", $F3="", $G3="", $H3=""),"",ROUND(($D3*Lists!$AD$20)+($E3*Lists!$AD$21)+($F3*Lists!$AD$22)+($G3*Lists!$AD$23)+($H3*Lists!$AD$24),2)) -> 2.2 | J3: J. Park | K3: 46127 | L3: Stable, well-managed
A4: R-0003 | B4: APM-0003 | C4: =IF($B4="","",IFERROR(VLOOKUP($B4,'Application Portfolio'!$A$2:$B$1000,2,FALSE()),"")) -> Payment Processor | D4: 4 | E4: 5 | F4: 4 | G4: 3 | H4: 4 | I4: =IF(OR($B4="", $D4="", $E4="", $F4="", $G4="", $H4=""),"",ROUND(($D4*Lists!$AD$20)+($E4*Lists!$AD$21)+($F4*Lists!$AD$22)+($G4*Lists!$AD$23)+($H4*Lists!$AD$24),2)) -> 4 | J4: R. Singh | K4: 46127 | L4: Compliance scope high, single-threaded ownership
A5: R-0004 | B5: APM-0004 | C5: =IF($B5="","",IFERROR(VLOOKUP($B5,'Application Portfolio'!$A$2:$B$1000,2,FALSE()),"")) -> Legacy CRM | D5: 3 | E5: 3 | F5: 4 | G5: 5 | H5: 5 | I5: =IF(OR($B5="", $D5="", $E5="", $F5="", $G5="", $H5=""),"",ROUND(($D5*Lists!$AD$20)+($E5*Lists!$AD$21)+($F5*Lists!$AD$22)+($G5*Lists!$AD$23)+($H5*Lists!$AD$24),2)) -> 4 | J5: M. Chen | K5: 46127 | L5: Vendor EOL announced; no internal expertise left
A6: R-0005 | B6: APM-0005 | C6: =IF($B6="","",IFERROR(VLOOKUP($B6,'Application Portfolio'!$A$2:$B$1000,2,FALSE()),"")) -> Marketing Analytics | D6: 2 | E6: 2 | F6: 2 | G6: 2 | H6: 3 | I6: =IF(OR($B6="", $D6="", $E6="", $F6="", $G6="", $H6=""),"",ROUND(($D6*Lists!$AD$20)+($E6*Lists!$AD$21)+($F6*Lists!$AD$22)+($G6*Lists!$AD$23)+($H6*Lists!$AD$24),2)) -> 2.2 | J6: L. Ramirez | K6: 46127 | L6: Low risk overall
A7: R-0006 | B7: APM-0006 | C7: =IF($B7="","",IFERROR(VLOOKUP($B7,'Application Portfolio'!$A$2:$B$1000,2,FALSE()),"")) -> Financial Reconciliation | D7: 4 | E7: 3 | F7: 4 | G7: 2 | H7: 3 | I7: =IF(OR($B7="", $D7="", $E7="", $F7="", $G7="", $H7=""),"",ROUND(($D7*Lists!$AD$20)+($E7*Lists!$AD$21)+($F7*Lists!$AD$22)+($G7*Lists!$AD$23)+($H7*Lists!$AD$24),2)) -> 3.2 | J7: K. Osei | K7: 46127 | L7: Ops resilience concerns - no DR tested
A8: R-0007 | B8: APM-0007 | C8: =IF($B8="","",IFERROR(VLOOKUP($B8,'Application Portfolio'!$A$2:$B$1000,2,FALSE()),"")) -> Partner API Gateway | D8: 3 | E8: 4 | F8: 3 | G8: 3 | H8: 2 | I8: =IF(OR($B8="", $D8="", $E8="", $F8="", $G8="", $H8=""),"",ROUND(($D8*Lists!$AD$20)+($E8*Lists!$AD$21)+($F8*Lists!$AD$22)+($G8*Lists!$AD$23)+($H8*Lists!$AD$24),2)) -> 3 | J8: T. Morgan | K8: 46127 | L8: Moderate - compliance attention needed
I9: =IF(OR($B9="", $D9="", $E9="", $F9="", $G9="", $H9=""),"",ROUND(($D9*Lists!$AD$20)+($E9*Lists!$AD$21)+($F9*Lists!$AD$22)+($G9*Lists!$AD$23)+($H9*Lists!$AD$24),2))
I10: =IF(OR($B10="", $D10="", $E10="", $F10="", $G10="", $H10=""),"",ROUND(($D10*Lists!$AD$20)+($E10*Lists!$AD$21)+($F10*Lists!$AD$22)+($G10*Lists!$AD$23)+($H10*Lists!$AD$24),2))
I11: =IF(OR($B11="", $D11="", $E11="", $F11="", $G11="", $H11=""),"",ROUND(($D11*Lists!$AD$20)+($E11*Lists!$AD$21)+($F11*Lists!$AD$22)+($G11*Lists!$AD$23)+($H11*Lists!$AD$24),2))
I12: =IF(OR($B12="", $D12="", $E12="", $F12="", $G12="", $H12=""),"",ROUND(($D12*Lists!$AD$20)+($E12*Lists!$AD$21)+($F12*Lists!$AD$22)+($G12*Lists!$AD$23)+($H12*Lists!$AD$24),2))
I13: =IF(OR($B13="", $D13="", $E13="", $F13="", $G13="", $H13=""),"",ROUND(($D13*Lists!$AD$20)+($E13*Lists!$AD$21)+($F13*Lists!$AD$22)+($G13*Lists!$AD$23)+($H13*Lists!$AD$24),2))
I14: =IF(OR($B14="", $D14="", $E14="", $F14="", $G14="", $H14=""),"",ROUND(($D14*Lists!$AD$20)+($E14*Lists!$AD$21)+($F14*Lists!$AD$22)+($G14*Lists!$AD$23)+($H14*Lists!$AD$24),2))
I15: =IF(OR($B15="", $D15="", $E15="", $F15="", $G15="", $H15=""),"",ROUND(($D15*Lists!$AD$20)+($E15*Lists!$AD$21)+($F15*Lists!$AD$22)+($G15*Lists!$AD$23)+($H15*Lists!$AD$24),2))
I16: =IF(OR($B16="", $D16="", $E16="", $F16="", $G16="", $H16=""),"",ROUND(($D16*Lists!$AD$20)+($E16*Lists!$AD$21)+($F16*Lists!$AD$22)+($G16*Lists!$AD$23)+($H16*Lists!$AD$24),2))
I17: =IF(OR($B17="", $D17="", $E17="", $F17="", $G17="", $H17=""),"",ROUND(($D17*Lists!$AD$20)+($E17*Lists!$AD$21)+($F17*Lists!$AD$22)+($G17*Lists!$AD$23)+($H17*Lists!$AD$24),2))
I18: =IF(OR($B18="", $D18="", $E18="", $F18="", $G18="", $H18=""),"",ROUND(($D18*Lists!$AD$20)+($E18*Lists!$AD$21)+($F18*Lists!$AD$22)+($G18*Lists!$AD$23)+($H18*Lists!$AD$24),2))
I19: =IF(OR($B19="", $D19="", $E19="", $F19="", $G19="", $H19=""),"",ROUND(($D19*Lists!$AD$20)+($E19*Lists!$AD$21)+($F19*Lists!$AD$22)+($G19*Lists!$AD$23)+($H19*Lists!$AD$24),2))
I20: =IF(OR($B20="", $D20="", $E20="", $F20="", $G20="", $H20=""),"",ROUND(($D20*Lists!$AD$20)+($E20*Lists!$AD$21)+($F20*Lists!$AD$22)+($G20*Lists!$AD$23)+($H20*Lists!$AD$24),2))
... I31: =IF(OR($B31="", $D31="", $E31="", $F31="", $G31="", $H31=""),"",ROUND(($D31*Lists!$AD$20)+($E31*Lists!$AD$21)+($F31*Lists!$AD$22)+($G31*Lists!$AD$23)+($H31*Lists!$AD$24),2))
C32: =IF($B32="","",IFERROR(VLOOKUP($B32,'Application Portfolio'!$A$2:$B$1000,2,FALSE()),"")) | I32: =IF(OR($B32="", $D32="", $E32="", $F32="", $G32="", $H32=""),"",ROUND(($D32*Lists!$AD$20)+($E32*Lists!$AD$21)+($F32*Lists!$AD$22)+($G32*Lists!$AD$23)+($H32*Lists!$AD$24),2))
C33: =IF($B33="","",IFERROR(VLOOKUP($B33,'Application Portfolio'!$A$2:$B$1000,2,FALSE()),"")) | I33: =IF(OR($B33="", $D33="", $E33="", $F33="", $G33="", $H33=""),"",ROUND(($D33*Lists!$AD$20)+($E33*Lists!$AD$21)+($F33*Lists!$AD$22)+($G33*Lists!$AD$23)+($H33*Lists!$AD$24),2))
C34: =IF($B34="","",IFERROR(VLOOKUP($B34,'Application Portfolio'!$A$2:$B$1000,2,FALSE()),"")) | I34: =IF(OR($B34="", $D34="", $E34="", $F34="", $G34="", $H34=""),"",ROUND(($D34*Lists!$AD$20)+($E34*Lists!$AD$21)+($F34*Lists!$AD$22)+($G34*Lists!$AD$23)+($H34*Lists!$AD$24),2))
C35: =IF($B35="","",IFERROR(VLOOKUP($B35,'Application Portfolio'!$A$2:$B$1000,2,FALSE()),"")) | I35: =IF(OR($B35="", $D35="", $E35="", $F35="", $G35="", $H35=""),"",ROUND(($D35*Lists!$AD$20)+($E35*Lists!$AD$21)+($F35*Lists!$AD$22)+($G35*Lists!$AD$23)+($H35*Lists!$AD$24),2))
C36: =IF($B36="","",IFERROR(VLOOKUP($B36,'Application Portfolio'!$A$2:$B$1000,2,FALSE()),"")) | I36: =IF(OR($B36="", $D36="", $E36="", $F36="", $G36="", $H36=""),"",ROUND(($D36*Lists!$AD$20)+($E36*Lists!$AD$21)+($F36*Lists!$AD$22)+($G36*Lists!$AD$23)+($H36*Lists!$AD$24),2))
C37: =IF($B37="","",IFERROR(VLOOKUP($B37,'Application Portfolio'!$A$2:$B$1000,2,FALSE()),"")) | I37: =IF(OR($B37="", $D37="", $E37="", $F37="", $G37="", $H37=""),"",ROUND(($D37*Lists!$AD$20)+($E37*Lists!$AD$21)+($F37*Lists!$AD$22)+($G37*Lists!$AD$23)+($H37*Lists!$AD$24),2))
C38: =IF($B38="","",IFERROR(VLOOKUP($B38,'Application Portfolio'!$A$2:$B$1000,2,FALSE()),"")) | I38: =IF(OR($B38="", $D38="", $E38="", $F38="", $G38="", $H38=""),"",ROUND(($D38*Lists!$AD$20)+($E38*Lists!$AD$21)+($F38*Lists!$AD$22)+($G38*Lists!$AD$23)+($H38*Lists!$AD$24),2))
C39: =IF($B39="","",IFERROR(VLOOKUP($B39,'Application Portfolio'!$A$2:$B$1000,2,FALSE()),"")) | I39: =IF(OR($B39="", $D39="", $E39="", $F39="", $G39="", $H39=""),"",ROUND(($D39*Lists!$AD$20)+($E39*Lists!$AD$21)+($F39*Lists!$AD$22)+($G39*Lists!$AD$23)+($H39*Lists!$AD$24),2))
C40: =IF($B40="","",IFERROR(VLOOKUP($B40,'Application Portfolio'!$A$2:$B$1000,2,FALSE()),"")) | I40: =IF(OR($B40="", $D40="", $E40="", $F40="", $G40="", $H40=""),"",ROUND(($D40*Lists!$AD$20)+($E40*Lists!$AD$21)+($F40*Lists!$AD$22)+($G40*Lists!$AD$23)+($H40*Lists!$AD$24),2))
C41: =IF($B41="","",IFERROR(VLOOKUP($B41,'Application Portfolio'!$A$2:$B$1000,2,FALSE()),"")) | I41: =IF(OR($B41="", $D41="", $E41="", $F41="", $G41="", $H41=""),"",ROUND(($D41*Lists!$AD$20)+($E41*Lists!$AD$21)+($F41*Lists!$AD$22)+($G41*Lists!$AD$23)+($H41*Lists!$AD$24),2))
C42: =IF($B42="","",IFERROR(VLOOKUP($B42,'Application Portfolio'!$A$2:$B$1000,2,FALSE()),"")) | I42: =IF(OR($B42="", $D42="", $E42="", $F42="", $G42="", $H42=""),"",ROUND(($D42*Lists!$AD$20)+($E42*Lists!$AD$21)+($F42*Lists!$AD$22)+($G42*Lists!$AD$23)+($H42*Lists!$AD$24),2))
C43: =IF($B43="","",IFERROR(VLOOKUP($B43,'Application Portfolio'!$A$2:$B$1000,2,FALSE()),"")) | I43: =IF(OR($B43="", $D43="", $E43="", $F43="", $G43="", $H43=""),"",ROUND(($D43*Lists!$AD$20)+($E43*Lists!$AD$21)+($F43*Lists!$AD$22)+($G43*Lists!$AD$23)+($H43*Lists!$AD$24),2))
... C1000: =IF($B1000="","",IFERROR(VLOOKUP($B1000,'Application Portfolio'!$A$2:$B$1000,2,FALSE()),"")) | I1000: =IF(OR($B1000="", $D1000="", $E1000="", $F1000="", $G1000="", $H1000=""),"",ROUND(($D1000*Lists!$AD$20)+($E1000*Lists!$AD$21)+($F1000*Lists!$AD$22)+($G1000*Lists!$AD$23)+($H1000*Lists!$AD$24),2))

Sheet Application Portfolio
A1: App ID | B1: Application Name | C1: Description | D1: Product/Service (Capability) | E1: Business Owner | F1: IT Owner | G1: Vendor | H1: Hosting Model | I1: Strategic Alignment (1-5) | J1: Clinical / Business Criticality (1-5) | K1: User Reach & Dependency (1-5) | L1: Differentiation (1-5) | M1: Regulatory Necessity (1-5) | N1: Business Value (BV) | O1: Risk Score (R) | P1: Annual Run Cost (1-5) | Q1: Cost Trend (1-5) | R1: Cost Transparency (1-5) | S1: Modernization Cost (1-5) | T1: Cost Score (C) | U1: Technology Currency (1-5) | V1: Architecture Quality (1-5) | W1: Integration Complexity (1-5) | X1: Data Architecture Fit (1-5) | Y1: Technical Debt (1-5) | Z1: Technical Health (TH) | AA1: Composite Portfolio Score (CPS) | AB1: TIME Classification | AC1: Clinical Criticality Flag | AD1: Compliance Exposure Flag | AE1: Quadrant (Value vs Risk) | AF1: Notes | AG1: Total Annual Cost ($) | AH1: Open Debt Items | AI1: Open Debt Score
A2: APM-0001 | B2: Customer Portal | C2: Patient and member self-service portal: appointments, bills, statements, and secure messaging. | D2: Patient Engagement | E2: VP Digital Health | F2: J. Park | G2: In-house | H2: Public Cloud | I2: 5 | J2: 5 | K2: 5 | L2: 4 | M2: 3 | N2: =IF(OR($B2="", $I2="", $J2="", $K2="", $L2="", $M2=""),"",ROUND(($I2*Lists!$AD$2)+($J2*Lists!$AD$3)+($K2*Lists!$AD$4)+($L2*Lists!$AD$5)+($M2*Lists!$AD$6),2)) -> 4.4 | O2: =IF($A2="","",IFERROR(VLOOKUP($A2,'Risk Register'!$B$2:$I$1000,8,FALSE()),"")) -> 3.4 | P2: 4 | Q2: 4 | R2: 3 | S2: 4 | T2: =IF(OR($B2="", $P2="", $Q2="", $R2="", $S2=""),"",ROUND(($P2*Lists!$AD$7)+($Q2*Lists!$AD$8)+($R2*Lists!$AD$9)+($S2*Lists!$AD$10),2)) -> 3.75 | U2: 2 | V2: 2 | W2: 2 | X2: 3 | Y2: 2 | Z2: =IF(OR($B2="", $U2="", $V2="", $W2="", $X2="", $Y2=""),"",ROUND(($U2*Lists!$AD$11)+($V2*Lists!$AD$12)+($W2*Lists!$AD$13)+($X2*Lists!$AD$14)+($Y2*Lists!$AD$15),2)) -> 2.2 | AA2: =IF(OR($B2="", $N2="", $O2="", $T2="", $Z2=""),"",ROUND(($N2*Lists!$AD$16)-($O2*Lists!$AD$17)-($T2*Lists!$AD$18)+($Z2*Lists!$AD$19),2)) -> -0.14 | AB2: =IF(OR($B2="", $N2="", $Z2=""),"",IF($N2>=Lists!$AG$2,IF($Z2>=Lists!$AG$3,"Invest","Migrate"),IF($Z2>=Lists!$AG$3,"Tolerate","Eliminate"))) -> Migrate | AC2: =IF($B2="","",IF($J2>=4,"Yes","")) -> Yes | AD2: =IF($A2="","",IFERROR(IF(VLOOKUP($A2,'Risk Register'!$B$2:$H$1000,4,FALSE())>=4,"Yes",""),"")) -> Yes | AE2: =IF(OR($N2="", $O2=""),"",IF($N2>=Lists!$AG$2,IF($O2>=Lists!$AG$4,"High Value / High Risk","High Value / Low Risk"),IF($O2>=Lists!$AG$4,"Low Value / High Risk","Low Value / Low Risk"))) -> High Value / Low Risk | AH2: =IF($B2="","",COUNTIFS('Debt Backlog'!$AF$2:$AF$1000,$A2,'Debt Backlog'!$B$2:$B$1000,"<>",'Debt Backlog'!$N$2:$N$1000,"<>Done",'Debt Backlog'!$N$2:$N$1000,"<>Won't Fix",'Debt Backlog'!$N$2:$N$1000,"<>Duplicate")) -> 2 | AI2: =IF($B2="","",ROUND(SUMIFS('Debt Backlog'!$L$2:$L$1000,'Debt Backlog'!$AF$2:$AF$1000,$A2,'Debt Backlog'!$B$2:$B$1000,"<>",'Debt Backlog'!$N$2:$N$1000,"<>Done",'Debt Backlog'!$N$2:$N$1000,"<>Won't Fix",'Debt Backlog'!$N$2:$N$1000,"<>Duplicate"),2)) -> 3.73
A3: APM-0002 | B3: Order Management System | C3: Supply and pharmacy order orchestration across hospitals, clinics, and distribution centers. | D3: Supply Chain | E3: COO | F3: M. Chen | G3: Oracle | H3: Private Cloud | I3: 5 | J3: 5 | K3: 4 | L3: 3 | M3: 3 | N3: =IF(OR($B3="", $I3="", $J3="", $K3="", $L3="", $M3=""),"",ROUND(($I3*Lists!$AD$2)+($J3*Lists!$AD$3)+($K3*Lists!$AD$4)+($L3*Lists!$AD$5)+($M3*Lists!$AD$6),2)) -> 4 | O3: =IF($A3="","",IFERROR(VLOOKUP($A3,'Risk Register'!$B$2:$I$1000,8,FALSE()),"")) -> 2.2 | P3: 3 | Q3: 3 | R3: 3 | S3: 3 | T3: =IF(OR($B3="", $P3="", $Q3="", $R3="", $S3=""),"",ROUND(($P3*Lists!$AD$7)+($Q3*Lists!$AD$8)+($R3*Lists!$AD$9)+($S3*Lists!$AD$10),2)) -> 3 | U3: 4 | V3: 4 | W3: 4 | X3: 4 | Y3: 3 | Z3: =IF(OR($B3="", $U3="", $V3="", $W3="", $X3="", $Y3=""),"",ROUND(($U3*Lists!$AD$11)+($V3*Lists!$AD$12)+($W3*Lists!$AD$13)+($X3*Lists!$AD$14)+($Y3*Lists!$AD$15),2)) -> 3.8 | AA3: =IF(OR($B3="", $N3="", $O3="", $T3="", $Z3=""),"",ROUND(($N3*Lists!$AD$16)-($O3*Lists!$AD$17)-($T3*Lists!$AD$18)+($Z3*Lists!$AD$19),2)) -> 0.65 | AB3: =IF(OR($B3="", $N3="", $Z3=""),"",IF($N3>=Lists!$AG$2,IF($Z3>=Lists!$AG$3,"Invest","Migrate"),IF($Z3>=Lists!$AG$3,"Tolerate","Eliminate"))) -> Invest | AC3: =IF($B3="","",IF($J3>=4,"Yes","")) -> Yes | AD3: =IF($A3="","",IFERROR(IF(VLOOKUP($A3,'Risk Register'!$B$2:$H$1000,4,FALSE())>=4,"Yes",""),"")) | AE3: =IF(OR($N3="", $O3=""),"",IF($N3>=Lists!$AG$2,IF($O3>=Lists!$AG$4,"High Value / High Risk","High Value / Low Risk"),IF($O3>=Lists!$AG$4,"Low Value / High Risk","Low Value / Low Risk"))) -> High Value / Low Risk | AH3: =IF($B3="","",COUNTIFS('Debt Backlog'!$AF$2:$AF$1000,$A3,'Debt Backlog'!$B$2:$B$1000,"<>",'Debt Backlog'!$N$2:$N$1000,"<>Done",'Debt Backlog'!$N$2:$N$1000,"<>Won't Fix",'Debt Backlog'!$N$2:$N$1000,"<>Duplicate")) -> 1 | AI3: =IF($B3="","",ROUND(SUMIFS('Debt Backlog'!$L$2:$L$1000,'Debt Backlog'!$AF$2:$AF$1000,$A3,'Debt Backlog'!$B$2:$B$1000,"<>",'Debt Backlog'!$N$2:$N$1000,"<>Done",'Debt Backlog'!$N$2:$N$1000,"<>Won't Fix",'Debt Backlog'!$N$2:$N$1000,"<>Duplicate"),2)) -> 3
A4: APM-0003 | B4: Payment Processor | C4: Patient payment gateway: card and HSA payments, payment plans, and fraud screening. | D4: Revenue Cycle | E4: VP Revenue Cycle | F4: R. Singh | G4: In-house | H4: Private Cloud | I4: 5 | J4: 5 | K4: 5 | L4: 5 | M4: 5 | N4: =IF(OR($B4="", $I4="", $J4="", $K4="", $L4="", $M4=""),"",ROUND(($I4*Lists!$AD$2)+($J4*Lists!$AD$3)+($K4*Lists!$AD$4)+($L4*Lists!$AD$5)+($M4*Lists!$AD$6),2)) -> 5 | O4: =IF($A4="","",IFERROR(VLOOKUP($A4,'Risk Register'!$B$2:$I$1000,8,FALSE()),"")) -> 4 | P4: 4 | Q4: 3 | R4: 3 | S4: 4 | T4: =IF(OR($B4="", $P4="", $Q4="", $R4="", $S4=""),"",ROUND(($P4*Lists!$AD$7)+($Q4*Lists!$AD$8)+($R4*Lists!$AD$9)+($S4*Lists!$AD$10),2)) -> 3.5 | U4: 3 | V4: 2 | W4: 2 | X4: 3 | Y4: 2 | Z4: =IF(OR($B4="", $U4="", $V4="", $W4="", $X4="", $Y4=""),"",ROUND(($U4*Lists!$AD$11)+($V4*Lists!$AD$12)+($W4*Lists!$AD$13)+($X4*Lists!$AD$14)+($Y4*Lists!$AD$15),2)) -> 2.4 | AA4: =IF(OR($B4="", $N4="", $O4="", $T4="", $Z4=""),"",ROUND(($N4*Lists!$AD$16)-($O4*Lists!$AD$17)-($T4*Lists!$AD$18)+($Z4*Lists!$AD$19),2)) -> -0.03 | AB4: =IF(OR($B4="", $N4="", $Z4=""),"",IF($N4>=Lists!$AG$2,IF($Z4>=Lists!$AG$3,"Invest","Migrate"),IF($Z4>=Lists!$AG$3,"Tolerate","Eliminate"))) -> Migrate | AC4: =IF($B4="","",IF($J4>=4,"Yes","")) -> Yes | AD4: =IF($A4="","",IFERROR(IF(VLOOKUP($A4,'Risk Register'!$B$2:$H$1000,4,FALSE())>=4,"Yes",""),"")) -> Yes | AE4: =IF(OR($N4="", $O4=""),"",IF($N4>=Lists!$AG$2,IF($O4>=Lists!$AG$4,"High Value / High Risk","High Value / Low Risk"),IF($O4>=Lists!$AG$4,"Low Value / High Risk","Low Value / Low Risk"))) -> High Value / High Risk | AH4: =IF($B4="","",COUNTIFS('Debt Backlog'!$AF$2:$AF$1000,$A4,'Debt Backlog'!$B$2:$B$1000,"<>",'Debt Backlog'!$N$2:$N$1000,"<>Done",'Debt Backlog'!$N$2:$N$1000,"<>Won't Fix",'Debt Backlog'!$N$2:$N$1000,"<>Duplicate")) -> 1 | AI4: =IF($B4="","",ROUND(SUMIFS('Debt Backlog'!$L$2:$L$1000,'Debt Backlog'!$AF$2:$AF$1000,$A4,'Debt Backlog'!$B$2:$B$1000,"<>",'Debt Backlog'!$N$2:$N$1000,"<>Done",'Debt Backlog'!$N$2:$N$1000,"<>Won't Fix",'Debt Backlog'!$N$2:$N$1000,"<>Duplicate"),2)) -> 3
A5: APM-0004 | B5: Legacy CRM | C5: Referral and provider-relations CRM in sunset. Superseded by the new cloud CRM; only 3 users remain. | D5: Provider Relations | E5: VP Network Development | F5: M. Chen | G5: Siebel | H5: On-Premise | I5: 1 | J5: 2 | K5: 1 | L5: 1 | M5: 1 | N5: =IF(OR($B5="", $I5="", $J5="", $K5="", $L5="", $M5=""),"",ROUND(($I5*Lists!$AD$2)+($J5*Lists!$AD$3)+($K5*Lists!$AD$4)+($L5*Lists!$AD$5)+($M5*Lists!$AD$6),2)) -> 1.2 | O5: =IF($A5="","",IFERROR(VLOOKUP($A5,'Risk Register'!$B$2:$I$1000,8,FALSE()),"")) -> 4 | P5: 4 | Q5: 5 | R5: 4 | S5: 5 | T5: =IF(OR($B5="", $P5="", $Q5="", $R5="", $S5=""),"",ROUND(($P5*Lists!$AD$7)+($Q5*Lists!$AD$8)+($R5*Lists!$AD$9)+($S5*Lists!$AD$10),2)) -> 4.5 | U5: 1 | V5: 1 | W5: 2 | X5: 1 | Y5: 1 | Z5: =IF(OR($B5="", $U5="", $V5="", $W5="", $X5="", $Y5=""),"",ROUND(($U5*Lists!$AD$11)+($V5*Lists!$AD$12)+($W5*Lists!$AD$13)+($X5*Lists!$AD$14)+($Y5*Lists!$AD$15),2)) -> 1.2 | AA5: =IF(OR($B5="", $N5="", $O5="", $T5="", $Z5=""),"",ROUND(($N5*Lists!$AD$16)-($O5*Lists!$AD$17)-($T5*Lists!$AD$18)+($Z5*Lists!$AD$19),2)) -> -1.53 | AB5: =IF(OR($B5="", $N5="", $Z5=""),"",IF($N5>=Lists!$AG$2,IF($Z5>=Lists!$AG$3,"Invest","Migrate"),IF($Z5>=Lists!$AG$3,"Tolerate","Eliminate"))) -> Eliminate | AC5: =IF($B5="","",IF($J5>=4,"Yes","")) | AD5: =IF($A5="","",IFERROR(IF(VLOOKUP($A5,'Risk Register'!$B$2:$H$1000,4,FALSE())>=4,"Yes",""),"")) | AE5: =IF(OR($N5="", $O5=""),"",IF($N5>=Lists!$AG$2,IF($O5>=Lists!$AG$4,"High Value / High Risk","High Value / Low Risk"),IF($O5>=Lists!$AG$4,"Low Value / High Risk","Low Value / Low Risk"))) -> Low Value / High Risk | AH5: =IF($B5="","",COUNTIFS('Debt Backlog'!$AF$2:$AF$1000,$A5,'Debt Backlog'!$B$2:$B$1000,"<>",'Debt Backlog'!$N$2:$N$1000,"<>Done",'Debt Backlog'!$N$2:$N$1000,"<>Won't Fix",'Debt Backlog'!$N$2:$N$1000,"<>Duplicate")) -> 0 | AI5: =IF($B5="","",ROUND(SUMIFS('Debt Backlog'!$L$2:$L$1000,'Debt Backlog'!$AF$2:$AF$1000,$A5,'Debt Backlog'!$B$2:$B$1000,"<>",'Debt Backlog'!$N$2:$N$1000,"<>Done",'Debt Backlog'!$N$2:$N$1000,"<>Won't Fix",'Debt Backlog'!$N$2:$N$1000,"<>Duplicate"),2)) -> 0
