Workbook

Sheet Overview
A1: Technical Debt Carry Cost Optimizer (Preview)
A2: The carry-cost math and priority ranking, per item, for a portfolio of up to 40 debt items. The full version adds the constrained multi-year sequencer.
A3: Inputs live on Parameters and Debt Portfolio (shaded cells). Everything here recalculates from them.
A5: Plan Parameters | E5: Portfolio at a Glance
A6: Organization | B6: =Parameters!B6 -> Example Healthcare Software Co | E6: Items in portfolio | F6: =COUNTA('Debt Portfolio'!B2:B41) -> 12
A7: Planning horizon (years) | B7: =Parameters!B7 -> 5 | E7: Open items | F7: =COUNTIFS('Debt Portfolio'!B2:B41,"<>",'Debt Portfolio'!E2:E41,"Open") -> 12
A8: Annual budget ($) | B8: =Parameters!B8 -> 2000000 | E8: Open items ranked | F8: =COUNT('Debt Portfolio'!Z2:Z41) -> 12
A9: Annual capacity (engineer-days) | B9: =Parameters!B9 -> 750 | E9: Items others depend on | F9: =COUNTIFS('Debt Portfolio'!W2:W41,"Yes",'Debt Portfolio'!E2:E41,"Open") -> 1
A10: Discount rate | B10: =Parameters!B10 -> 0.08 | E10: Total remediation cost, open items ($) | F10: =SUMIFS('Debt Portfolio'!F2:F41,'Debt Portfolio'!E2:E41,"Open") -> 3885000
A12: Cost of Doing Nothing | E12: Open Items by Priority
A13: Annual cost of doing nothing, today ($) | B13: =SUMIFS('Debt Portfolio'!M2:M41,'Debt Portfolio'!E2:E41,"Open") -> 8547000 | E13: High | F13: =COUNTIFS('Debt Portfolio'!X2:X41,"High",'Debt Portfolio'!E2:E41,"Open") -> 6
A14: NPV cost if nothing is remediated ($) | B14: =SUMIFS('Debt Portfolio'!N2:N41,'Debt Portfolio'!E2:E41,"Open") -> 39659039 | E14: Medium | F14: =COUNTIFS('Debt Portfolio'!X2:X41,"Medium",'Debt Portfolio'!E2:E41,"Open") -> 5
A15: NPV savings if everything were fixed in year 1 ($) | B15: =SUMIFS('Debt Portfolio'!O2:O41,'Debt Portfolio'!E2:E41,"Open") -> 28147928 | E15: Low | F15: =COUNTIFS('Debt Portfolio'!X2:X41,"Low",'Debt Portfolio'!E2:E41,"Open") -> 1
A16: Items that pay back within the horizon | B16: =COUNTIFS('Debt Portfolio'!U2:U41,">0",'Debt Portfolio'!E2:E41,"Open") -> 11
A17: Items to accept as carry (no payback) | B17: =COUNTIFS('Debt Portfolio'!T2:T41,"Accept",'Debt Portfolio'!E2:E41,"Open") -> 1
A19: Ranked List (top 12 by priority, then NPV savings)
A20: Rank | B20: ID | C20: Name | D20: Priority | E20: Best Year | F20: Best NPV Savings ($)
A21: 1 | B21: =IFERROR(INDEX('Debt Portfolio'!$A$2:$A$41,MATCH(1,'Debt Portfolio'!$Z$2:$Z$41,0)),"") -> OPS-001 | C21: =IFERROR(INDEX('Debt Portfolio'!$B$2:$B$41,MATCH(1,'Debt Portfolio'!$Z$2:$Z$41,0)),"") -> Cloud cost waste - 24/7 dev environments and no RIs | D21: =IFERROR(INDEX('Debt Portfolio'!$X$2:$X$41,MATCH(1,'Debt Portfolio'!$Z$2:$Z$41,0)),"") -> High | E21: =IFERROR(INDEX('Debt Portfolio'!$T$2:$T$41,MATCH(1,'Debt Portfolio'!$Z$2:$Z$41,0)),"") -> 1 | F21: =IFERROR(INDEX('Debt Portfolio'!$U$2:$U$41,MATCH(1,'Debt Portfolio'!$Z$2:$Z$41,0)),"") -> 16160474
A22: 2 | B22: =IFERROR(INDEX('Debt Portfolio'!$A$2:$A$41,MATCH(2,'Debt Portfolio'!$Z$2:$Z$41,0)),"") -> SEC-001 | C22: =IFERROR(INDEX('Debt Portfolio'!$B$2:$B$41,MATCH(2,'Debt Portfolio'!$Z$2:$Z$41,0)),"") -> SOC 2 Type II expired - access control remediation needed | D22: =IFERROR(INDEX('Debt Portfolio'!$X$2:$X$41,MATCH(2,'Debt Portfolio'!$Z$2:$Z$41,0)),"") -> High | E22: =IFERROR(INDEX('Debt Portfolio'!$T$2:$T$41,MATCH(2,'Debt Portfolio'!$Z$2:$Z$41,0)),"") -> 1 | F22: =IFERROR(INDEX('Debt Portfolio'!$U$2:$U$41,MATCH(2,'Debt Portfolio'!$Z$2:$Z$41,0)),"") -> 5184561.7
A23: 3 | B23: =IFERROR(INDEX('Debt Portfolio'!$A$2:$A$41,MATCH(3,'Debt Portfolio'!$Z$2:$Z$41,0)),"") -> PEOPLE-001 | C23: =IFERROR(INDEX('Debt Portfolio'!$B$2:$B$41,MATCH(3,'Debt Portfolio'!$Z$2:$Z$41,0)),"") -> Key person concentration on platform code | D23: =IFERROR(INDEX('Debt Portfolio'!$X$2:$X$41,MATCH(3,'Debt Portfolio'!$Z$2:$Z$41,0)),"") -> High | E23: =IFERROR(INDEX('Debt Portfolio'!$T$2:$T$41,MATCH(3,'Debt Portfolio'!$Z$2:$Z$41,0)),"") -> 1 | F23: =IFERROR(INDEX('Debt Portfolio'!$U$2:$U$41,MATCH(3,'Debt Portfolio'!$Z$2:$Z$41,0)),"") -> 1938187.6
A24: 4 | B24: =IFERROR(INDEX('Debt Portfolio'!$A$2:$A$41,MATCH(4,'Debt Portfolio'!$Z$2:$Z$41,0)),"") -> IP-001 | C24: =IFERROR(INDEX('Debt Portfolio'!$B$2:$B$41,MATCH(4,'Debt Portfolio'!$Z$2:$Z$41,0)),"") -> Missing IP assignments for 12 engineers | D24: =IFERROR(INDEX('Debt Portfolio'!$X$2:$X$41,MATCH(4,'Debt Portfolio'!$Z$2:$Z$41,0)),"") -> High | E24: =IFERROR(INDEX('Debt Portfolio'!$T$2:$T$41,MATCH(4,'Debt Portfolio'!$Z$2:$Z$41,0)),"") -> 1 | F24: =IFERROR(INDEX('Debt Portfolio'!$U$2:$U$41,MATCH(4,'Debt Portfolio'!$Z$2:$Z$41,0)),"") -> 1573434.5
A25: 5 | B25: =IFERROR(INDEX('Debt Portfolio'!$A$2:$A$41,MATCH(5,'Debt Portfolio'!$Z$2:$Z$41,0)),"") -> OPS-002 | C25: =IFERROR(INDEX('Debt Portfolio'!$B$2:$B$41,MATCH(5,'Debt Portfolio'!$Z$2:$Z$41,0)),"") -> DR plan never validated | D25: =IFERROR(INDEX('Debt Portfolio'!$X$2:$X$41,MATCH(5,'Debt Portfolio'!$Z$2:$Z$41,0)),"") -> High | E25: =IFERROR(INDEX('Debt Portfolio'!$T$2:$T$41,MATCH(5,'Debt Portfolio'!$Z$2:$Z$41,0)),"") -> 1 | F25: =IFERROR(INDEX('Debt Portfolio'!$U$2:$U$41,MATCH(5,'Debt Portfolio'!$Z$2:$Z$41,0)),"") -> 1429366.1
A26: 6 | B26: =IFERROR(INDEX('Debt Portfolio'!$A$2:$A$41,MATCH(6,'Debt Portfolio'!$Z$2:$Z$41,0)),"") -> SEC-002 | C26: =IFERROR(INDEX('Debt Portfolio'!$B$2:$B$41,MATCH(6,'Debt Portfolio'!$Z$2:$Z$41,0)),"") -> Two unremediated High pen test findings | D26: =IFERROR(INDEX('Debt Portfolio'!$X$2:$X$41,MATCH(6,'Debt Portfolio'!$Z$2:$Z$41,0)),"") -> High | E26: =IFERROR(INDEX('Debt Portfolio'!$T$2:$T$41,MATCH(6,'Debt Portfolio'!$Z$2:$Z$41,0)),"") -> 1 | F26: =IFERROR(INDEX('Debt Portfolio'!$U$2:$U$41,MATCH(6,'Debt Portfolio'!$Z$2:$Z$41,0)),"") -> 633812.16
A27: 7 | B27: =IFERROR(INDEX('Debt Portfolio'!$A$2:$A$41,MATCH(7,'Debt Portfolio'!$Z$2:$Z$41,0)),"") -> ARCH-001 | C27: =IFERROR(INDEX('Debt Portfolio'!$B$2:$B$41,MATCH(7,'Debt Portfolio'!$Z$2:$Z$41,0)),"") -> Multi-tenancy migration abandoned mid-flight | D27: =IFERROR(INDEX('Debt Portfolio'!$X$2:$X$41,MATCH(7,'Debt Portfolio'!$Z$2:$Z$41,0)),"") -> Medium | E27: =IFERROR(INDEX('Debt Portfolio'!$T$2:$T$41,MATCH(7,'Debt Portfolio'!$Z$2:$Z$41,0)),"") -> 1 | F27: =IFERROR(INDEX('Debt Portfolio'!$U$2:$U$41,MATCH(7,'Debt Portfolio'!$Z$2:$Z$41,0)),"") -> 583984.38
A28: 8 | B28: =IFERROR(INDEX('Debt Portfolio'!$A$2:$A$41,MATCH(8,'Debt Portfolio'!$Z$2:$Z$41,0)),"") -> ARCH-002 | C28: =IFERROR(INDEX('Debt Portfolio'!$B$2:$B$41,MATCH(8,'Debt Portfolio'!$Z$2:$Z$41,0)),"") -> PostgreSQL 11 EOL - upgrade required | D28: =IFERROR(INDEX('Debt Portfolio'!$X$2:$X$41,MATCH(8,'Debt Portfolio'!$Z$2:$Z$41,0)),"") -> Medium | E28: =IFERROR(INDEX('Debt Portfolio'!$T$2:$T$41,MATCH(8,'Debt Portfolio'!$Z$2:$Z$41,0)),"") -> 1 | F28: =IFERROR(INDEX('Debt Portfolio'!$U$2:$U$41,MATCH(8,'Debt Portfolio'!$Z$2:$Z$41,0)),"") -> 345563.18
A29: 9 | B29: =IFERROR(INDEX('Debt Portfolio'!$A$2:$A$41,MATCH(9,'Debt Portfolio'!$Z$2:$Z$41,0)),"") -> DATA-002 | C29: =IFERROR(INDEX('Debt Portfolio'!$B$2:$B$41,MATCH(9,'Debt Portfolio'!$Z$2:$Z$41,0)),"") -> Three different MAU definitions across teams | D29: =IFERROR(INDEX('Debt Portfolio'!$X$2:$X$41,MATCH(9,'Debt Portfolio'!$Z$2:$Z$41,0)),"") -> Medium | E29: =IFERROR(INDEX('Debt Portfolio'!$T$2:$T$41,MATCH(9,'Debt Portfolio'!$Z$2:$Z$41,0)),"") -> 1 | F29: =IFERROR(INDEX('Debt Portfolio'!$U$2:$U$41,MATCH(9,'Debt Portfolio'!$Z$2:$Z$41,0)),"") -> 171306.29
A30: 10 | B30: =IFERROR(INDEX('Debt Portfolio'!$A$2:$A$41,MATCH(10,'Debt Portfolio'!$Z$2:$Z$41,0)),"") -> DATA-001 | C30: =IFERROR(INDEX('Debt Portfolio'!$B$2:$B$41,MATCH(10,'Debt Portfolio'!$Z$2:$Z$41,0)),"") -> Customer churn calculation bug | D30: =IFERROR(INDEX('Debt Portfolio'!$X$2:$X$41,MATCH(10,'Debt Portfolio'!$Z$2:$Z$41,0)),"") -> Medium | E30: =IFERROR(INDEX('Debt Portfolio'!$T$2:$T$41,MATCH(10,'Debt Portfolio'!$Z$2:$Z$41,0)),"") -> 1 | F30: =IFERROR(INDEX('Debt Portfolio'!$U$2:$U$41,MATCH(10,'Debt Portfolio'!$Z$2:$Z$41,0)),"") -> 133900.79
A31: 11 | B31: =IFERROR(INDEX('Debt Portfolio'!$A$2:$A$41,MATCH(11,'Debt Portfolio'!$Z$2:$Z$41,0)),"") -> PROCESS-001 | C31: =IFERROR(INDEX('Debt Portfolio'!$B$2:$B$41,MATCH(11,'Debt Portfolio'!$Z$2:$Z$41,0)),"") -> No DORA metrics tracking | D31: =IFERROR(INDEX('Debt Portfolio'!$X$2:$X$41,MATCH(11,'Debt Portfolio'!$Z$2:$Z$41,0)),"") -> Medium | E31: =IFERROR(INDEX('Debt Portfolio'!$T$2:$T$41,MATCH(11,'Debt Portfolio'!$Z$2:$Z$41,0)),"") -> 1 | F31: =IFERROR(INDEX('Debt Portfolio'!$U$2:$U$41,MATCH(11,'Debt Portfolio'!$Z$2:$Z$41,0)),"") -> 60318.017
A32: 12 | B32: =IFERROR(INDEX('Debt Portfolio'!$A$2:$A$41,MATCH(12,'Debt Portfolio'!$Z$2:$Z$41,0)),"") -> ARCH-003 | C32: =IFERROR(INDEX('Debt Portfolio'!$B$2:$B$41,MATCH(12,'Debt Portfolio'!$Z$2:$Z$41,0)),"") -> Code modernization to support multi-tenancy | D32: =IFERROR(INDEX('Debt Portfolio'!$X$2:$X$41,MATCH(12,'Debt Portfolio'!$Z$2:$Z$41,0)),"") -> Low | E32: =IFERROR(INDEX('Debt Portfolio'!$T$2:$T$41,MATCH(12,'Debt Portfolio'!$Z$2:$Z$41,0)),"") -> Accept | F32: =IFERROR(INDEX('Debt Portfolio'!$U$2:$U$41,MATCH(12,'Debt Portfolio'!$Z$2:$Z$41,0)),"") -> -66980.771
A34: What the full optimizer adds
A35: A multi-year remediation plan: each item placed in the first year where annual budget, engineering capacity, and its dependency chain allow, with items that fit nowhere marked as deferred and their carried cost reported as accepted risk.
A36: A rationale per item explaining why it landed in its year, the year-by-year budget and capacity utilization, and the NPV of the plan against no action.
A37: In the production version: a learned priority scorer, skill-mix capacity pools, sensitivity ranges on cost inputs, and quarterly replanning. Available through direct engagement.

Sheet Parameters
A1: Technical Debt Carry Cost Optimizer (Preview)
A2: Multi-year remediation sequencing that minimizes carry cost plus remediation cost plus expected incident cost, within an annual budget and engineering capacity.
A3: Shaded cells on this sheet and on Debt Portfolio are inputs. Everything else is calculated. Lists holds the dropdown options and priority thresholds.
A5: Plan Parameters
A6: Organization | B6: Example Healthcare Software Co
A7: Planning horizon (years, 1 to 5) | B7: 5
A8: Annual remediation budget ($) | B8: 2000000
A9: Annual capacity (engineer-days) | B9: 750
A10: Discount rate | B10: 0.08
A11: Loaded cost per engineer-day ($, reference only) | B11: 1200
A13: How the math works
A14: Cost if never remediated, over the horizon T: sum over years t of carry x (1+growth)^(t-1) x discount(t), plus incident probability x incident cost x discount(t).
A15: Cost if remediated in year Y: the same carry and incident terms for years 1 to Y, plus remediation cost x discount(Y).
A16: NPV savings of remediating in year Y = cost if never minus cost if remediated in year Y. Best year is the Y with the highest savings.
A17: Priority class comes from the savings ratio (year-1 NPV savings divided by remediation cost) against the thresholds on Lists, with a bump for items that others depend on.
A18: The plan is a greedy allocation: items are ranked by priority class, then NPV savings, then carry growth; the full version places each in the first year where budget, capacity, and its dependency allow.
A19: This preview stops at the ranking. The multi-year sequencer, the rationale generator, and the production optimizer are available through direct engagement.

Sheet Lists
A1: Domain | C1: Status | E1: Priority | F1: Savings Ratio >= | G1: Sort Order | I1: Dependency-target bump (added to savings ratio)
A2: Architecture | C2: Open | E2: High | F2: 3 | G2: 1 | I2: 1
A3: Code | C3: Done | E3: Medium | F3: 1 | G3: 2
A4: Infrastructure | C4: Accepted | E4: Low | F4: -1000000000 | G4: 3
A5: Data
A6: Security | E6: Priority thresholds: an item is High if its savings ratio is at or above the High threshold, Medium if at or above the Medium threshold, otherwise Low. Edit the shaded cells.
A7: People
A8: Process
A9: General

Sheet Debt Portfolio
A1: ID | B1: Name | C1: Domain | D1: Description | E1: Status | F1: Remediation Cost ($) | G1: Annual Carry Cost ($) | H1: Carry Growth Rate | I1: Incident Probability / yr | J1: Incident Cost ($) | K1: Effort (engineer-days) | L1: Depends On (ID) | M1: Expected Annual Loss ($) | N1: NPV Cost If Never ($) | O1: NPV Savings Y1 ($) | P1: NPV Savings Y2 ($) | Q1: NPV Savings Y3 ($) | R1: NPV Savings Y4 ($) | S1: NPV Savings Y5 ($) | T1: Best Year | U1: Best NPV Savings ($) | V1: Savings Ratio | W1: Depended On By Others | X1: Priority | Y1: Sort Key | Z1: Rank | AA1: Planned Year (full version) | AB1: NPV Cost Fix Y1 ($) | AC1: NPV Cost Fix Y2 ($) | AD1: NPV Cost Fix Y3 ($) | AE1: NPV Cost Fix Y4 ($) | AF1: NPV Cost Fix Y5 ($) | AG1: Carry Y1 ($) | AH1: Carry Y2 ($) | AI1: Carry Y3 ($) | AJ1: Carry Y4 ($) | AK1: Carry Y5 ($)
A2: ARCH-001 | B2: Multi-tenancy migration abandoned mid-flight | C2: Architecture | D2: Single-tenant deployment requires manual provisioning, blocks enterprise expansion | E2: Open | F2: 1500000 | G2: 350000 | H2: 0.12 | I2: 0.06 | J2: 3000000 | K2: 360 | M2: =IF($B2="","",$G2+$I2*$J2) -> 530000 | N2: =IF($B2="","",IF(Parameters!$B$7<=0,0,IF(ABS((1+$H2)/(1+Parameters!$B$10)-1)<0.000001,Parameters!$B$7*$G2/(1+Parameters!$B$10),$G2/(1+Parameters!$B$10)*(1-((1+$H2)/(1+Parameters!$B$10))^Parameters!$B$7)/(1-(1+$H2)/(1+Parameters!$B$10))))+IF(Parameters!$B$7<=0,0,IF(Parameters!$B$10=0,Parameters!$B$7*$I2*$J2,$I2*$J2*(1-(1/(1+Parameters!$B$10))^Parameters!$B$7)/Parameters!$B$10))) -> 2463614 | O2: =IF(OR($B2="",1>Parameters!$B$7),"",$N2-AB2) -> 583984.38 | P2: =IF(OR($B2="",2>Parameters!$B$7),"",$N2-AC2) -> 196467.23 | Q2: =IF(OR($B2="",3>Parameters!$B$7),"",$N2-AD2) -> -199686.81 | R2: =IF(OR($B2="",4>Parameters!$B$7),"",$N2-AE2) -> -605221.01 | S2: =IF(OR($B2="",5>Parameters!$B$7),"",$N2-AF2) -> -1020874.8 | T2: =IF($B2="","",IF(MAX($O2:$S2)<0,"Accept",MATCH(MAX($O2:$S2),$O2:$S2,0))) -> 1 | U2: =IF($B2="","",MAX($O2:$S2)) -> 583984.38 | V2: =IF($B2="","",IF($F2>0,ROUND($O2/$F2,2),IF(N($O2)>0,Lists!$F$2,0))+IF($W2="Yes",Lists!$I$2,0)) -> 1.39 | W2: =IF($B2="","",IF(COUNTIFS($L$2:$L$41,$A2,$E$2:$E$41,"Open",$A$2:$A$41,"<>"&$A2)>0,"Yes","No")) -> Yes | X2: =IF($B2="","",IF($V2>=Lists!$F$2,"High",IF($V2>=Lists!$F$3,"Medium","Low"))) -> Medium | Y2: =IF(OR($B2="",$E2<>"Open"),"",IF($L2="",(INDEX(Lists!$G$2:$G$4,MATCH($X2,Lists!$E$2:$E$4,0))*1000000000000-$U2-$H2),IFERROR(MAX((INDEX(Lists!$G$2:$G$4,MATCH($X2,Lists!$E$2:$E$4,0))*1000000000000-$U2-$H2),INDEX($Y$2:$Y$41,MATCH($L2,$A$2:$A$41,0))+1),(INDEX(Lists!$G$2:$G$4,MATCH($X2,Lists!$E$2:$E$4,0))*1000000000000-$U2-$H2)))) -> 1.9999994e+12 | Z2: =IF($Y2="","",RANK($Y2,$Y$2:$Y$41,1)+COUNTIF($Y$2:$Y2,$Y2)-1) -> 7 | AA2: ="" | AB2: =IF(OR($B2="",1>Parameters!$B$7),"",IF(1<=0,0,IF(ABS((1+$H2)/(1+Parameters!$B$10)-1)<0.000001,1*$G2/(1+Parameters!$B$10),$G2/(1+Parameters!$B$10)*(1-((1+$H2)/(1+Parameters!$B$10))^1)/(1-(1+$H2)/(1+Parameters!$B$10))))+$F2/(1+Parameters!$B$10)^1+IF(1<=0,0,IF(Parameters!$B$10=0,1*$I2*$J2,$I2*$J2*(1-(1/(1+Parameters!$B$10))^1)/Parameters!$B$10))) -> 1879629.6 | AC2: =IF(OR($B2="",2>Parameters!$B$7),"",IF(2<=0,0,IF(ABS((1+$H2)/(1+Parameters!$B$10)-1)<0.000001,2*$G2/(1+Parameters!$B$10),$G2/(1+Parameters!$B$10)*(1-((1+$H2)/(1+Parameters!$B$10))^2)/(1-(1+$H2)/(1+Parameters!$B$10))))+$F2/(1+Parameters!$B$10)^2+IF(2<=0,0,IF(Parameters!$B$10=0,2*$I2*$J2,$I2*$J2*(1-(1/(1+Parameters!$B$10))^2)/Parameters!$B$10))) -> 2267146.8 | AD2: =IF(OR($B2="",3>Parameters!$B$7),"",IF(3<=0,0,IF(ABS((1+$H2)/(1+Parameters!$B$10)-1)<0.000001,3*$G2/(1+Parameters!$B$10),$G2/(1+Parameters!$B$10)*(1-((1+$H2)/(1+Parameters!$B$10))^3)/(1-(1+$H2)/(1+Parameters!$B$10))))+$F2/(1+Parameters!$B$10)^3+IF(3<=0,0,IF(Parameters!$B$10=0,3*$I2*$J2,$I2*$J2*(1-(1/(1+Parameters!$B$10))^3)/Parameters!$B$10))) -> 2663300.8 | AE2: =IF(OR($B2="",4>Parameters!$B$7),"",IF(4<=0,0,IF(ABS((1+$H2)/(1+Parameters!$B$10)-1)<0.000001,4*$G2/(1+Parameters!$B$10),$G2/(1+Parameters!$B$10)*(1-((1+$H2)/(1+Parameters!$B$10))^4)/(1-(1+$H2)/(1+Parameters!$B$10))))+$F2/(1+Parameters!$B$10)^4+IF(4<=0,0,IF(Parameters!$B$10=0,4*$I2*$J2,$I2*$J2*(1-(1/(1+Parameters!$B$10))^4)/Parameters!$B$10))) -> 3068835 | AF2: =IF(OR($B2="",5>Parameters!$B$7),"",IF(5<=0,0,IF(ABS((1+$H2)/(1+Parameters!$B$10)-1)<0.000001,5*$G2/(1+Parameters!$B$10),$G2/(1+Parameters!$B$10)*(1-((1+$H2)/(1+Parameters!$B$10))^5)/(1-(1+$H2)/(1+Parameters!$B$10))))+$F2/(1+Parameters!$B$10)^5+IF(5<=0,0,IF(Parameters!$B$10=0,5*$I2*$J2,$I2*$J2*(1-(1/(1+Parameters!$B$10))^5)/Parameters!$B$10))) -> 3484488.8 | AG2: =IF(OR($B2="",1>Parameters!$B$7),"",$G2*(1+$H2)^(1-1)) -> 350000 | AH2: =IF(OR($B2="",2>Parameters!$B$7),"",$G2*(1+$H2)^(2-1)) -> 392000 | AI2: =IF(OR($B2="",3>Parameters!$B$7),"",$G2*(1+$H2)^(3-1)) -> 439040 | AJ2: =IF(OR($B2="",4>Parameters!$B$7),"",$G2*(1+$H2)^(4-1)) -> 491724.8 | AK2: =IF(OR($B2="",5>Parameters!$B$7),"",$G2*(1+$H2)^(5-1)) -> 550731.78
A3: SEC-001 | B3: SOC 2 Type II expired - access control remediation needed | C3: Security | D3: Enterprise pipeline blocked, growing as more customers require SOC 2 | E3: Open | F3: 250000 | G3: 800000 | H3: 0.2 | I3: 0.1 | J3: 5000000 | K3: 90 | M3: =IF($B3="","",$G3+$I3*$J3) -> 1300000 | N3: =IF($B3="","",IF(Parameters!$B$7<=0,0,IF(ABS((1+$H3)/(1+Parameters!$B$10)-1)<0.000001,Parameters!$B$7*$G3/(1+Parameters!$B$10),$G3/(1+Parameters!$B$10)*(1-((1+$H3)/(1+Parameters!$B$10))^Parameters!$B$7)/(1-(1+$H3)/(1+Parameters!$B$10))))+IF(Parameters!$B$7<=0,0,IF(Parameters!$B$10=0,Parameters!$B$7*$I3*$J3,$I3*$J3*(1-(1/(1+Parameters!$B$10))^Parameters!$B$7)/Parameters!$B$10))) -> 6619746.9 | O3: =IF(OR($B3="",1>Parameters!$B$7),"",$N3-AB3) -> 5184561.7 | P3: =IF(OR($B3="",2>Parameters!$B$7),"",$N3-AC3) -> 3949993.8 | Q3: =IF(OR($B3="",3>Parameters!$B$7),"",$N3-AD3) -> 2654459.6 | R3: =IF(OR($B3="",4>Parameters!$B$7),"",$N3-AE3) -> 1285540 | S3: =IF(OR($B3="",5>Parameters!$B$7),"",$N3-AF3) -> -170145.8 | T3: =IF($B3="","",IF(MAX($O3:$S3)<0,"Accept",MATCH(MAX($O3:$S3),$O3:$S3,0))) -> 1 | U3: =IF($B3="","",MAX($O3:$S3)) -> 5184561.7 | V3: =IF($B3="","",IF($F3>0,ROUND($O3/$F3,2),IF(N($O3)>0,Lists!$F$2,0))+IF($W3="Yes",Lists!$I$2,0)) -> 20.74 | W3: =IF($B3="","",IF(COUNTIFS($L$2:$L$41,$A3,$E$2:$E$41,"Open",$A$2:$A$41,"<>"&$A3)>0,"Yes","No")) -> No | X3: =IF($B3="","",IF($V3>=Lists!$F$2,"High",IF($V3>=Lists!$F$3,"Medium","Low"))) -> High | Y3: =IF(OR($B3="",$E3<>"Open"),"",IF($L3="",(INDEX(Lists!$G$2:$G$4,MATCH($X3,Lists!$E$2:$E$4,0))*1000000000000-$U3-$H3),IFERROR(MAX((INDEX(Lists!$G$2:$G$4,MATCH($X3,Lists!$E$2:$E$4,0))*1000000000000-$U3-$H3),INDEX($Y$2:$Y$41,MATCH($L3,$A$2:$A$41,0))+1),(INDEX(Lists!$G$2:$G$4,MATCH($X3,Lists!$E$2:$E$4,0))*1000000000000-$U3-$H3)))) -> 9.9999482e+11 | Z3: =IF($Y3="","",RANK($Y3,$Y$2:$Y$41,1)+COUNTIF($Y$2:$Y3,$Y3)-1) -> 2 | AA3: ="" | AB3: =IF(OR($B3="",1>Parameters!$B$7),"",IF(1<=0,0,IF(ABS((1+$H3)/(1+Parameters!$B$10)-1)<0.000001,1*$G3/(1+Parameters!$B$10),$G3/(1+Parameters!$B$10)*(1-((1+$H3)/(1+Parameters!$B$10))^1)/(1-(1+$H3)/(1+Parameters!$B$10))))+$F3/(1+Parameters!$B$10)^1+IF(1<=0,0,IF(Parameters!$B$10=0,1*$I3*$J3,$I3*$J3*(1-(1/(1+Parameters!$B$10))^1)/Parameters!$B$10))) -> 1435185.2 | AC3: =IF(OR($B3="",2>Parameters!$B$7),"",IF(2<=0,0,IF(ABS((1+$H3)/(1+Parameters!$B$10)-1)<0.000001,2*$G3/(1+Parameters!$B$10),$G3/(1+Parameters!$B$10)*(1-((1+$H3)/(1+Parameters!$B$10))^2)/(1-(1+$H3)/(1+Parameters!$B$10))))+$F3/(1+Parameters!$B$10)^2+IF(2<=0,0,IF(Parameters!$B$10=0,2*$I3*$J3,$I3*$J3*(1-(1/(1+Parameters!$B$10))^2)/Parameters!$B$10))) -> 2669753.1 | AD3: =IF(OR($B3="",3>Parameters!$B$7),"",IF(3<=0,0,IF(ABS((1+$H3)/(1+Parameters!$B$10)-1)<0.000001,3*$G3/(1+Parameters!$B$10),$G3/(1+Parameters!$B$10)*(1-((1+$H3)/(1+Parameters!$B$10))^3)/(1-(1+$H3)/(1+Parameters!$B$10))))+$F3/(1+Parameters!$B$10)^3+IF(3<=0,0,IF(Parameters!$B$10=0,3*$I3*$J3,$I3*$J3*(1-(1/(1+Parameters!$B$10))^3)/Parameters!$B$10))) -> 3965287.3 | AE3: =IF(OR($B3="",4>Parameters!$B$7),"",IF(4<=0,0,IF(ABS((1+$H3)/(1+Parameters!$B$10)-1)<0.000001,4*$G3/(1+Parameters!$B$10),$G3/(1+Parameters!$B$10)*(1-((1+$H3)/(1+Parameters!$B$10))^4)/(1-(1+$H3)/(1+Parameters!$B$10))))+$F3/(1+Parameters!$B$10)^4+IF(4<=0,0,IF(Parameters!$B$10=0,4*$I3*$J3,$I3*$J3*(1-(1/(1+Parameters!$B$10))^4)/Parameters!$B$10))) -> 5334206.9 | AF3: =IF(OR($B3="",5>Parameters!$B$7),"",IF(5<=0,0,IF(ABS((1+$H3)/(1+Parameters!$B$10)-1)<0.000001,5*$G3/(1+Parameters!$B$10),$G3/(1+Parameters!$B$10)*(1-((1+$H3)/(1+Parameters!$B$10))^5)/(1-(1+$H3)/(1+Parameters!$B$10))))+$F3/(1+Parameters!$B$10)^5+IF(5<=0,0,IF(Parameters!$B$10=0,5*$I3*$J3,$I3*$J3*(1-(1/(1+Parameters!$B$10))^5)/Parameters!$B$10))) -> 6789892.7 | AG3: =IF(OR($B3="",1>Parameters!$B$7),"",$G3*(1+$H3)^(1-1)) -> 800000 | AH3: =IF(OR($B3="",2>Parameters!$B$7),"",$G3*(1+$H3)^(2-1)) -> 960000 | AI3: =IF(OR($B3="",3>Parameters!$B$7),"",$G3*(1+$H3)^(3-1)) -> 1152000 | AJ3: =IF(OR($B3="",4>Parameters!$B$7),"",$G3*(1+$H3)^(4-1)) -> 1382400 | AK3: =IF(OR($B3="",5>Parameters!$B$7),"",$G3*(1+$H3)^(5-1)) -> 1658880
A4: SEC-002 | B4: Two unremediated High pen test findings | C4: Security | D4: Risk acceptance memos missing, regulatory exposure | E4: Open | F4: 80000 | G4: 50000 | H4: 0.15 | I4: 0.08 | J4: 2000000 | K4: 30 | M4: =IF($B4="","",$G4+$I4*$J4) -> 210000 | N4: =IF($B4="","",IF(Parameters!$B$7<=0,0,IF(ABS((1+$H4)/(1+Parameters!$B$10)-1)<0.000001,Parameters!$B$7*$G4/(1+Parameters!$B$10),$G4/(1+Parameters!$B$10)*(1-((1+$H4)/(1+Parameters!$B$10))^Parameters!$B$7)/(1-(1+$H4)/(1+Parameters!$B$10))))+IF(Parameters!$B$7<=0,0,IF(Parameters!$B$10=0,Parameters!$B$7*$I4*$J4,$I4*$J4*(1-(1/(1+Parameters!$B$10))^Parameters!$B$7)/Parameters!$B$10))) -> 902330.68 | O4: =IF(OR($B4="",1>Parameters!$B$7),"",$N4-AB4) -> 633812.16 | P4: =IF(OR($B4="",2>Parameters!$B$7),"",$N4-AC4) -> 452827.94 | Q4: =IF(OR($B4="",3>Parameters!$B$7),"",$N4-AD4) -> 278403.15 | R4: =IF(OR($B4="",4>Parameters!$B$7),"",$N4-AE4) -> 109608.14 | S4: =IF(OR($B4="",5>Parameters!$B$7),"",$N4-AF4) -> -54446.656 | T4: =IF($B4="","",IF(MAX($O4:$S4)<0,"Accept",MATCH(MAX($O4:$S4),$O4:$S4,0))) -> 1 | U4: =IF($B4="","",MAX($O4:$S4)) -> 633812.16 | V4: =IF($B4="","",IF($F4>0,ROUND($O4/$F4,2),IF(N($O4)>0,Lists!$F$2,0))+IF($W4="Yes",Lists!$I$2,0)) -> 7.92 | W4: =IF($B4="","",IF(COUNTIFS($L$2:$L$41,$A4,$E$2:$E$41,"Open",$A$2:$A$41,"<>"&$A4)>0,"Yes","No")) -> No | X4: =IF($B4="","",IF($V4>=Lists!$F$2,"High",IF($V4>=Lists!$F$3,"Medium","Low"))) -> High | Y4: =IF(OR($B4="",$E4<>"Open"),"",IF($L4="",(INDEX(Lists!$G$2:$G$4,MATCH($X4,Lists!$E$2:$E$4,0))*1000000000000-$U4-$H4),IFERROR(MAX((INDEX(Lists!$G$2:$G$4,MATCH($X4,Lists!$E$2:$E$4,0))*1000000000000-$U4-$H4),INDEX($Y$2:$Y$41,MATCH($L4,$A$2:$A$41,0))+1),(INDEX(Lists!$G$2:$G$4,MATCH($X4,Lists!$E$2:$E$4,0))*1000000000000-$U4-$H4)))) -> 9.9999937e+11 | Z4: =IF($Y4="","",RANK($Y4,$Y$2:$Y$41,1)+COUNTIF($Y$2:$Y4,$Y4)-1) -> 6 | AA4: ="" | AB4: =IF(OR($B4="",1>Parameters!$B$7),"",IF(1<=0,0,IF(ABS((1+$H4)/(1+Parameters!$B$10)-1)<0.000001,1*$G4/(1+Parameters!$B$10),$G4/(1+Parameters!$B$10)*(1-((1+$H4)/(1+Parameters!$B$10))^1)/(1-(1+$H4)/(1+Parameters!$B$10))))+$F4/(1+Parameters!$B$10)^1+IF(1<=0,0,IF(Parameters!$B$10=0,1*$I4*$J4,$I4*$J4*(1-(1/(1+Parameters!$B$10))^1)/Parameters!$B$10))) -> 268518.52 | AC4: =IF(OR($B4="",2>Parameters!$B$7),"",IF(2<=0,0,IF(ABS((1+$H4)/(1+Parameters!$B$10)-1)<0.000001,2*$G4/(1+Parameters!$B$10),$G4/(1+Parameters!$B$10)*(1-((1+$H4)/(1+Parameters!$B$10))^2)/(1-(1+$H4)/(1+Parameters!$B$10))))+$F4/(1+Parameters!$B$10)^2+IF(2<=0,0,IF(Parameters!$B$10=0,2*$I4*$J4,$I4*$J4*(1-(1/(1+Parameters!$B$10))^2)/Parameters!$B$10))) -> 449502.74 | AD4: =IF(OR($B4="",3>Parameters!$B$7),"",IF(3<=0,0,IF(ABS((1+$H4)/(1+Parameters!$B$10)-1)<0.000001,3*$G4/(1+Parameters!$B$10),$G4/(1+Parameters!$B$10)*(1-((1+$H4)/(1+Parameters!$B$10))^3)/(1-(1+$H4)/(1+Parameters!$B$10))))+$F4/(1+Parameters!$B$10)^3+IF(3<=0,0,IF(Parameters!$B$10=0,3*$I4*$J4,$I4*$J4*(1-(1/(1+Parameters!$B$10))^3)/Parameters!$B$10))) -> 623927.53 | AE4: =IF(OR($B4="",4>Parameters!$B$7),"",IF(4<=0,0,IF(ABS((1+$H4)/(1+Parameters!$B$10)-1)<0.000001,4*$G4/(1+Parameters!$B$10),$G4/(1+Parameters!$B$10)*(1-((1+$H4)/(1+Parameters!$B$10))^4)/(1-(1+$H4)/(1+Parameters!$B$10))))+$F4/(1+Parameters!$B$10)^4+IF(4<=0,0,IF(Parameters!$B$10=0,4*$I4*$J4,$I4*$J4*(1-(1/(1+Parameters!$B$10))^4)/Parameters!$B$10))) -> 792722.54 | AF4: =IF(OR($B4="",5>Parameters!$B$7),"",IF(5<=0,0,IF(ABS((1+$H4)/(1+Parameters!$B$10)-1)<0.000001,5*$G4/(1+Parameters!$B$10),$G4/(1+Parameters!$B$10)*(1-((1+$H4)/(1+Parameters!$B$10))^5)/(1-(1+$H4)/(1+Parameters!$B$10))))+$F4/(1+Parameters!$B$10)^5+IF(5<=0,0,IF(Parameters!$B$10=0,5*$I4*$J4,$I4*$J4*(1-(1/(1+Parameters!$B$10))^5)/Parameters!$B$10))) -> 956777.34 | AG4: =IF(OR($B4="",1>Parameters!$B$7),"",$G4*(1+$H4)^(1-1)) -> 50000 | AH4: =IF(OR($B4="",2>Parameters!$B$7),"",$G4*(1+$H4)^(2-1)) -> 57500 | AI4: =IF(OR($B4="",3>Parameters!$B$7),"",$G4*(1+$H4)^(3-1)) -> 66125 | AJ4: =IF(OR($B4="",4>Parameters!$B$7),"",$G4*(1+$H4)^(4-1)) -> 76043.75 | AK4: =IF(OR($B4="",5>Parameters!$B$7),"",$G4*(1+$H4)^(5-1)) -> 87450.312
A5: PEOPLE-001 | B5: Key person concentration on platform code | C5: People | D5: Two engineers own 60% of platform code, both vest at close | E5: Open | F5: 400000 | G5: 200000 | H5: 0.25 | I5: 0.2 | J5: 2000000 | K5: 120 | M5: =IF($B5="","",$G5+$I5*$J5) -> 600000 | N5: =IF($B5="","",IF(Parameters!$B$7<=0,0,IF(ABS((1+$H5)/(1+Parameters!$B$10)-1)<0.000001,Parameters!$B$7*$G5/(1+Parameters!$B$10),$G5/(1+Parameters!$B$10)*(1-((1+$H5)/(1+Parameters!$B$10))^Parameters!$B$7)/(1-(1+$H5)/(1+Parameters!$B$10))))+IF(Parameters!$B$7<=0,0,IF(Parameters!$B$10=0,Parameters!$B$7*$I5*$J5,$I5*$J5*(1-(1/(1+Parameters!$B$10))^Parameters!$B$7)/Parameters!$B$10))) -> 2864113.5 | O5: =IF(OR($B5="",1>Parameters!$B$7),"",$N5-AB5) -> 1938187.6 | P5: =IF(OR($B5="",2>Parameters!$B$7),"",$N5-AC5) -> 1408352.2 | Q5: =IF(OR($B5="",3>Parameters!$B$7),"",$N5-AD5) -> 868149.37 | R5: =IF(OR($B5="",4>Parameters!$B$7),"",$N5-AE5) -> 310537.35 | S5: =IF(OR($B5="",5>Parameters!$B$7),"",$N5-AF5) -> -272233.28 | T5: =IF($B5="","",IF(MAX($O5:$S5)<0,"Accept",MATCH(MAX($O5:$S5),$O5:$S5,0))) -> 1 | U5: =IF($B5="","",MAX($O5:$S5)) -> 1938187.6 | V5: =IF($B5="","",IF($F5>0,ROUND($O5/$F5,2),IF(N($O5)>0,Lists!$F$2,0))+IF($W5="Yes",Lists!$I$2,0)) -> 4.85 | W5: =IF($B5="","",IF(COUNTIFS($L$2:$L$41,$A5,$E$2:$E$41,"Open",$A$2:$A$41,"<>"&$A5)>0,"Yes","No")) -> No | X5: =IF($B5="","",IF($V5>=Lists!$F$2,"High",IF($V5>=Lists!$F$3,"Medium","Low"))) -> High | Y5: =IF(OR($B5="",$E5<>"Open"),"",IF($L5="",(INDEX(Lists!$G$2:$G$4,MATCH($X5,Lists!$E$2:$E$4,0))*1000000000000-$U5-$H5),IFERROR(MAX((INDEX(Lists!$G$2:$G$4,MATCH($X5,Lists!$E$2:$E$4,0))*1000000000000-$U5-$H5),INDEX($Y$2:$Y$41,MATCH($L5,$A$2:$A$41,0))+1),(INDEX(Lists!$G$2:$G$4,MATCH($X5,Lists!$E$2:$E$4,0))*1000000000000-$U5-$H5)))) -> 9.9999806e+11 | Z5: =IF($Y5="","",RANK($Y5,$Y$2:$Y$41,1)+COUNTIF($Y$2:$Y5,$Y5)-1) -> 3 | AA5: ="" | AB5: =IF(OR($B5="",1>Parameters!$B$7),"",IF(1<=0,0,IF(ABS((1+$H5)/(1+Parameters!$B$10)-1)<0.000001,1*$G5/(1+Parameters!$B$10),$G5/(1+Parameters!$B$10)*(1-((1+$H5)/(1+Parameters!$B$10))^1)/(1-(1+$H5)/(1+Parameters!$B$10))))+$F5/(1+Parameters!$B$10)^1+IF(1<=0,0,IF(Parameters!$B$10=0,1*$I5*$J5,$I5*$J5*(1-(1/(1+Parameters!$B$10))^1)/Parameters!$B$10))) -> 925925.93 | AC5: =IF(OR($B5="",2>Parameters!$B$7),"",IF(2<=0,0,IF(ABS((1+$H5)/(1+Parameters!$B$10)-1)<0.000001,2*$G5/(1+Parameters!$B$10),$G5/(1+Parameters!$B$10)*(1-((1+$H5)/(1+Parameters!$B$10))^2)/(1-(1+$H5)/(1+Parameters!$B$10))))+$F5/(1+Parameters!$B$10)^2+IF(2<=0,0,IF(Parameters!$B$10=0,2*$I5*$J5,$I5*$J5*(1-(1/(1+Parameters!$B$10))^2)/Parameters!$B$10))) -> 1455761.3 | AD5: =IF(OR($B5="",3>Parameters!$B$7),"",IF(3<=0,0,IF(ABS((1+$H5)/(1+Parameters!$B$10)-1)<0.000001,3*$G5/(1+Parameters!$B$10),$G5/(1+Parameters!$B$10)*(1-((1+$H5)/(1+Parameters!$B$10))^3)/(1-(1+$H5)/(1+Parameters!$B$10))))+$F5/(1+Parameters!$B$10)^3+IF(3<=0,0,IF(Parameters!$B$10=0,3*$I5*$J5,$I5*$J5*(1-(1/(1+Parameters!$B$10))^3)/Parameters!$B$10))) -> 1995964.2 | AE5: =IF(OR($B5="",4>Parameters!$B$7),"",IF(4<=0,0,IF(ABS((1+$H5)/(1+Parameters!$B$10)-1)<0.000001,4*$G5/(1+Parameters!$B$10),$G5/(1+Parameters!$B$10)*(1-((1+$H5)/(1+Parameters!$B$10))^4)/(1-(1+$H5)/(1+Parameters!$B$10))))+$F5/(1+Parameters!$B$10)^4+IF(4<=0,0,IF(Parameters!$B$10=0,4*$I5*$J5,$I5*$J5*(1-(1/(1+Parameters!$B$10))^4)/Parameters!$B$10))) -> 2553576.2 | AF5: =IF(OR($B5="",5>Parameters!$B$7),"",IF(5<=0,0,IF(ABS((1+$H5)/(1+Parameters!$B$10)-1)<0.000001,5*$G5/(1+Parameters!$B$10),$G5/(1+Parameters!$B$10)*(1-((1+$H5)/(1+Parameters!$B$10))^5)/(1-(1+$H5)/(1+Parameters!$B$10))))+$F5/(1+Parameters!$B$10)^5+IF(5<=0,0,IF(Parameters!$B$10=0,5*$I5*$J5,$I5*$J5*(1-(1/(1+Parameters!$B$10))^5)/Parameters!$B$10))) -> 3136346.8 | AG5: =IF(OR($B5="",1>Parameters!$B$7),"",$G5*(1+$H5)^(1-1)) -> 200000 | AH5: =IF(OR($B5="",2>Parameters!$B$7),"",$G5*(1+$H5)^(2-1)) -> 250000 | AI5: =IF(OR($B5="",3>Parameters!$B$7),"",$G5*(1+$H5)^(3-1)) -> 312500 | AJ5: =IF(OR($B5="",4>Parameters!$B$7),"",$G5*(1+$H5)^(4-1)) -> 390625 | AK5: =IF(OR($B5="",5>Parameters!$B$7),"",$G5*(1+$H5)^(5-1)) -> 488281.25
A6: OPS-001 | B6: Cloud cost waste - 24/7 dev environments and no RIs | C6: Infrastructure | D6: $4.4M annual waste, easy quick win | E6: Open | F6: 150000 | G6: 4400000 | H6: 0.08 | I6: 0.01 | J6: 100000 | K6: 60 | M6: =IF($B6="","",$G6+$I6*$J6) -> 4401000 | N6: =IF($B6="","",IF(Parameters!$B$7<=0,0,IF(ABS((1+$H6)/(1+Parameters!$B$10)-1)<0.000001,Parameters!$B$7*$G6/(1+Parameters!$B$10),$G6/(1+Parameters!$B$10)*(1-((1+$H6)/(1+Parameters!$B$10))^Parameters!$B$7)/(1-(1+$H6)/(1+Parameters!$B$10))))+IF(Parameters!$B$7<=0,0,IF(Parameters!$B$10=0,Parameters!$B$7*$I6*$J6,$I6*$J6*(1-(1/(1+Parameters!$B$10))^Parameters!$B$7)/Parameters!$B$10))) -> 20374363 | O6: =IF(OR($B6="",1>Parameters!$B$7),"",$N6-AB6) -> 16160474 | P6: =IF(OR($B6="",2>Parameters!$B$7),"",$N6-AC6) -> 12095831 | Q6: =IF(OR($B6="",3>Parameters!$B$7),"",$N6-AD6) -> 8030488.9 | R6: =IF(OR($B6="",4>Parameters!$B$7),"",$N6-AE6) -> 3964500.2 | S6: =IF(OR($B6="",5>Parameters!$B$7),"",$N6-AF6) -> -102087.48 | T6: =IF($B6="","",IF(MAX($O6:$S6)<0,"Accept",MATCH(MAX($O6:$S6),$O6:$S6,0))) -> 1 | U6: =IF($B6="","",MAX($O6:$S6)) -> 16160474 | V6: =IF($B6="","",IF($F6>0,ROUND($O6/$F6,2),IF(N($O6)>0,Lists!$F$2,0))+IF($W6="Yes",Lists!$I$2,0)) -> 107.74 | W6: =IF($B6="","",IF(COUNTIFS($L$2:$L$41,$A6,$E$2:$E$41,"Open",$A$2:$A$41,"<>"&$A6)>0,"Yes","No")) -> No | X6: =IF($B6="","",IF($V6>=Lists!$F$2,"High",IF($V6>=Lists!$F$3,"Medium","Low"))) -> High | Y6: =IF(OR($B6="",$E6<>"Open"),"",IF($L6="",(INDEX(Lists!$G$2:$G$4,MATCH($X6,Lists!$E$2:$E$4,0))*1000000000000-$U6-$H6),IFERROR(MAX((INDEX(Lists!$G$2:$G$4,MATCH($X6,Lists!$E$2:$E$4,0))*1000000000000-$U6-$H6),INDEX($Y$2:$Y$41,MATCH($L6,$A$2:$A$41,0))+1),(INDEX(Lists!$G$2:$G$4,MATCH($X6,Lists!$E$2:$E$4,0))*1000000000000-$U6-$H6)))) -> 9.9998384e+11 | Z6: =IF($Y6="","",RANK($Y6,$Y$2:$Y$41,1)+COUNTIF($Y$2:$Y6,$Y6)-1) -> 1 | AA6: ="" | AB6: =IF(OR($B6="",1>Parameters!$B$7),"",IF(1<=0,0,IF(ABS((1+$H6)/(1+Parameters!$B$10)-1)<0.000001,1*$G6/(1+Parameters!$B$10),$G6/(1+Parameters!$B$10)*(1-((1+$H6)/(1+Parameters!$B$10))^1)/(1-(1+$H6)/(1+Parameters!$B$10))))+$F6/(1+Parameters!$B$10)^1+IF(1<=0,0,IF(Parameters!$B$10=0,1*$I6*$J6,$I6*$J6*(1-(1/(1+Parameters!$B$10))^1)/Parameters!$B$10))) -> 4213888.9 | AC6: =IF(OR($B6="",2>Parameters!$B$7),"",IF(2<=0,0,IF(ABS((1+$H6)/(1+Parameters!$B$10)-1)<0.000001,2*$G6/(1+Parameters!$B$10),$G6/(1+Parameters!$B$10)*(1-((1+$H6)/(1+Parameters!$B$10))^2)/(1-(1+$H6)/(1+Parameters!$B$10))))+$F6/(1+Parameters!$B$10)^2+IF(2<=0,0,IF(Parameters!$B$10=0,2*$I6*$J6,$I6*$J6*(1-(1/(1+Parameters!$B$10))^2)/Parameters!$B$10))) -> 8278532.2 | AD6: =IF(OR($B6="",3>Parameters!$B$7),"",IF(3<=0,0,IF(ABS((1+$H6)/(1+Parameters!$B$10)-1)<0.000001,3*$G6/(1+Parameters!$B$10),$G6/(1+Parameters!$B$10)*(1-((1+$H6)/(1+Parameters!$B$10))^3)/(1-(1+$H6)/(1+Parameters!$B$10))))+$F6/(1+Parameters!$B$10)^3+IF(3<=0,0,IF(Parameters!$B$10=0,3*$I6*$J6,$I6*$J6*(1-(1/(1+Parameters!$B$10))^3)/Parameters!$B$10))) -> 12343874 | AE6: =IF(OR($B6="",4>Parameters!$B$7),"",IF(4<=0,0,IF(ABS((1+$H6)/(1+Parameters!$B$10)-1)<0.000001,4*$G6/(1+Parameters!$B$10),$G6/(1+Parameters!$B$10)*(1-((1+$H6)/(1+Parameters!$B$10))^4)/(1-(1+$H6)/(1+Parameters!$B$10))))+$F6/(1+Parameters!$B$10)^4+IF(4<=0,0,IF(Parameters!$B$10=0,4*$I6*$J6,$I6*$J6*(1-(1/(1+Parameters!$B$10))^4)/Parameters!$B$10))) -> 16409863 | AF6: =IF(OR($B6="",5>Parameters!$B$7),"",IF(5<=0,0,IF(ABS((1+$H6)/(1+Parameters!$B$10)-1)<0.000001,5*$G6/(1+Parameters!$B$10),$G6/(1+Parameters!$B$10)*(1-((1+$H6)/(1+Parameters!$B$10))^5)/(1-(1+$H6)/(1+Parameters!$B$10))))+$F6/(1+Parameters!$B$10)^5+IF(5<=0,0,IF(Parameters!$B$10=0,5*$I6*$J6,$I6*$J6*(1-(1/(1+Parameters!$B$10))^5)/Parameters!$B$10))) -> 20476451 | AG6: =IF(OR($B6="",1>Parameters!$B$7),"",$G6*(1+$H6)^(1-1)) -> 4400000 | AH6: =IF(OR($B6="",2>Parameters!$B$7),"",$G6*(1+$H6)^(2-1)) -> 4752000 | AI6: =IF(OR($B6="",3>Parameters!$B$7),"",$G6*(1+$H6)^(3-1)) -> 5132160 | AJ6: =IF(OR($B6="",4>Parameters!$B$7),"",$G6*(1+$H6)^(4-1)) -> 5542732.8 | AK6: =IF(OR($B6="",5>Parameters!$B$7),"",$G6*(1+$H6)^(5-1)) -> 5986151.4
A7: OPS-002 | B7: DR plan never validated | C7: Infrastructure | D7: 4-hour RTO claimed, never tested, last attempt failed | E7: Open | F7: 200000 | G7: 100000 | H7: 0.1 | I7: 0.05 | J7: 8000000 | K7: 90 | M7: =IF($B7="","",$G7+$I7*$J7) -> 500000 | N7: =IF($B7="","",IF(Parameters!$B$7<=0,0,IF(ABS((1+$H7)/(1+Parameters!$B$10)-1)<0.000001,Parameters!$B$7*$G7/(1+Parameters!$B$10),$G7/(1+Parameters!$B$10)*(1-((1+$H7)/(1+Parameters!$B$10))^Parameters!$B$7)/(1-(1+$H7)/(1+Parameters!$B$10))))+IF(Parameters!$B$7<=0,0,IF(Parameters!$B$10=0,Parameters!$B$7*$I7*$J7,$I7*$J7*(1-(1/(1+Parameters!$B$10))^Parameters!$B$7)/Parameters!$B$10))) -> 2077514.2 | O7: =IF(OR($B7="",1>Parameters!$B$7),"",$N7-AB7) -> 1429366.1 | P7: =IF(OR($B7="",2>Parameters!$B$7),"",$N7-AC7) -> 1005840.7 | Q7: =IF(OR($B7="",3>Parameters!$B$7),"",$N7-AD7) -> 604955.43 | R7: =IF(OR($B7="",4>Parameters!$B$7),"",$N7-AE7) -> 224871.49 | S7: =IF(OR($B7="",5>Parameters!$B$7),"",$N7-AF7) -> -136116.64 | T7: =IF($B7="","",IF(MAX($O7:$S7)<0,"Accept",MATCH(MAX($O7:$S7),$O7:$S7,0))) -> 1 | U7: =IF($B7="","",MAX($O7:$S7)) -> 1429366.1 | V7: =IF($B7="","",IF($F7>0,ROUND($O7/$F7,2),IF(N($O7)>0,Lists!$F$2,0))+IF($W7="Yes",Lists!$I$2,0)) -> 7.15 | W7: =IF($B7="","",IF(COUNTIFS($L$2:$L$41,$A7,$E$2:$E$41,"Open",$A$2:$A$41,"<>"&$A7)>0,"Yes","No")) -> No | X7: =IF($B7="","",IF($V7>=Lists!$F$2,"High",IF($V7>=Lists!$F$3,"Medium","Low"))) -> High | Y7: =IF(OR($B7="",$E7<>"Open"),"",IF($L7="",(INDEX(Lists!$G$2:$G$4,MATCH($X7,Lists!$E$2:$E$4,0))*1000000000000-$U7-$H7),IFERROR(MAX((INDEX(Lists!$G$2:$G$4,MATCH($X7,Lists!$E$2:$E$4,0))*1000000000000-$U7-$H7),INDEX($Y$2:$Y$41,MATCH($L7,$A$2:$A$41,0))+1),(INDEX(Lists!$G$2:$G$4,MATCH($X7,Lists!$E$2:$E$4,0))*1000000000000-$U7-$H7)))) -> 9.9999857e+11 | Z7: =IF($Y7="","",RANK($Y7,$Y$2:$Y$41,1)+COUNTIF($Y$2:$Y7,$Y7)-1) -> 5 | AA7: ="" | AB7: =IF(OR($B7="",1>Parameters!$B$7),"",IF(1<=0,0,IF(ABS((1+$H7)/(1+Parameters!$B$10)-1)<0.000001,1*$G7/(1+Parameters!$B$10),$G7/(1+Parameters!$B$10)*(1-((1+$H7)/(1+Parameters!$B$10))^1)/(1-(1+$H7)/(1+Parameters!$B$10))))+$F7/(1+Parameters!$B$10)^1+IF(1<=0,0,IF(Parameters!$B$10=0,1*$I7*$J7,$I7*$J7*(1-(1/(1+Parameters!$B$10))^1)/Parameters!$B$10))) -> 648148.15 | AC7: =IF(OR($B7="",2>Parameters!$B$7),"",IF(2<=0,0,IF(ABS((1+$H7)/(1+Parameters!$B$10)-1)<0.000001,2*$G7/(1+Parameters!$B$10),$G7/(1+Parameters!$B$10)*(1-((1+$H7)/(1+Parameters!$B$10))^2)/(1-(1+$H7)/(1+Parameters!$B$10))))+$F7/(1+Parameters!$B$10)^2+IF(2<=0,0,IF(Parameters!$B$10=0,2*$I7*$J7,$I7*$J7*(1-(1/(1+Parameters!$B$10))^2)/Parameters!$B$10))) -> 1071673.5 | AD7: =IF(OR($B7="",3>Parameters!$B$7),"",IF(3<=0,0,IF(ABS((1+$H7)/(1+Parameters!$B$10)-1)<0.000001,3*$G7/(1+Parameters!$B$10),$G7/(1+Parameters!$B$10)*(1-((1+$H7)/(1+Parameters!$B$10))^3)/(1-(1+$H7)/(1+Parameters!$B$10))))+$F7/(1+Parameters!$B$10)^3+IF(3<=0,0,IF(Parameters!$B$10=0,3*$I7*$J7,$I7*$J7*(1-(1/(1+Parameters!$B$10))^3)/Parameters!$B$10))) -> 1472558.8 | AE7: =IF(OR($B7="",4>Parameters!$B$7),"",IF(4<=0,0,IF(ABS((1+$H7)/(1+Parameters!$B$10)-1)<0.000001,4*$G7/(1+Parameters!$B$10),$G7/(1+Parameters!$B$10)*(1-((1+$H7)/(1+Parameters!$B$10))^4)/(1-(1+$H7)/(1+Parameters!$B$10))))+$F7/(1+Parameters!$B$10)^4+IF(4<=0,0,IF(Parameters!$B$10=0,4*$I7*$J7,$I7*$J7*(1-(1/(1+Parameters!$B$10))^4)/Parameters!$B$10))) -> 1852642.7 | AF7: =IF(OR($B7="",5>Parameters!$B$7),"",IF(5<=0,0,IF(ABS((1+$H7)/(1+Parameters!$B$10)-1)<0.000001,5*$G7/(1+Parameters!$B$10),$G7/(1+Parameters!$B$10)*(1-((1+$H7)/(1+Parameters!$B$10))^5)/(1-(1+$H7)/(1+Parameters!$B$10))))+$F7/(1+Parameters!$B$10)^5+IF(5<=0,0,IF(Parameters!$B$10=0,5*$I7*$J7,$I7*$J7*(1-(1/(1+Parameters!$B$10))^5)/Parameters!$B$10))) -> 2213630.9 | AG7: =IF(OR($B7="",1>Parameters!$B$7),"",$G7*(1+$H7)^(1-1)) -> 100000 | AH7: =IF(OR($B7="",2>Parameters!$B$7),"",$G7*(1+$H7)^(2-1)) -> 110000 | AI7: =IF(OR($B7="",3>Parameters!$B$7),"",$G7*(1+$H7)^(3-1)) -> 121000 | AJ7: =IF(OR($B7="",4>Parameters!$B$7),"",$G7*(1+$H7)^(4-1)) -> 133100 | AK7: =IF(OR($B7="",5>Parameters!$B$7),"",$G7*(1+$H7)^(5-1)) -> 146410
A8: DATA-001 | B8: Customer churn calculation bug | C8: Data | D8: Understates churn 1.5pp for 18 months, board reporting issue | E8: Open | F8: 75000 | G8: 50000 | H8: 0.05 | I8: 0.02 | J8: 500000 | K8: 30 | M8: =IF($B8="","",$G8+$I8*$J8) -> 60000 | N8: =IF($B8="","",IF(Parameters!$B$7<=0,0,IF(ABS((1+$H8)/(1+Parameters!$B$10)-1)<0.000001,Parameters!$B$7*$G8/(1+Parameters!$B$10),$G8/(1+Parameters!$B$10)*(1-((1+$H8)/(1+Parameters!$B$10))^Parameters!$B$7)/(1-(1+$H8)/(1+Parameters!$B$10))))+IF(Parameters!$B$7<=0,0,IF(Parameters!$B$10=0,Parameters!$B$7*$I8*$J8,$I8*$J8*(1-(1/(1+Parameters!$B$10))^Parameters!$B$7)/Parameters!$B$10))) -> 258900.79 | O8: =IF(OR($B8="",1>Parameters!$B$7),"",$N8-AB8) -> 133900.79 | P8: =IF(OR($B8="",2>Parameters!$B$7),"",$N8-AC8) -> 85461.147 | Q8: =IF(OR($B8="",3>Parameters!$B$7),"",$N8-AD8) -> 38525.816 | R8: =IF(OR($B8="",4>Parameters!$B$7),"",$N8-AE8) -> -6958.7505 | S8: =IF(OR($B8="",5>Parameters!$B$7),"",$N8-AF8) -> -51043.74 | T8: =IF($B8="","",IF(MAX($O8:$S8)<0,"Accept",MATCH(MAX($O8:$S8),$O8:$S8,0))) -> 1 | U8: =IF($B8="","",MAX($O8:$S8)) -> 133900.79 | V8: =IF($B8="","",IF($F8>0,ROUND($O8/$F8,2),IF(N($O8)>0,Lists!$F$2,0))+IF($W8="Yes",Lists!$I$2,0)) -> 1.79 | W8: =IF($B8="","",IF(COUNTIFS($L$2:$L$41,$A8,$E$2:$E$41,"Open",$A$2:$A$41,"<>"&$A8)>0,"Yes","No")) -> No | X8: =IF($B8="","",IF($V8>=Lists!$F$2,"High",IF($V8>=Lists!$F$3,"Medium","Low"))) -> Medium | Y8: =IF(OR($B8="",$E8<>"Open"),"",IF($L8="",(INDEX(Lists!$G$2:$G$4,MATCH($X8,Lists!$E$2:$E$4,0))*1000000000000-$U8-$H8),IFERROR(MAX((INDEX(Lists!$G$2:$G$4,MATCH($X8,Lists!$E$2:$E$4,0))*1000000000000-$U8-$H8),INDEX($Y$2:$Y$41,MATCH($L8,$A$2:$A$41,0))+1),(INDEX(Lists!$G$2:$G$4,MATCH($X8,Lists!$E$2:$E$4,0))*1000000000000-$U8-$H8)))) -> 1.9999999e+12 | Z8: =IF($Y8="","",RANK($Y8,$Y$2:$Y$41,1)+COUNTIF($Y$2:$Y8,$Y8)-1) -> 10 | AA8: ="" | AB8: =IF(OR($B8="",1>Parameters!$B$7),"",IF(1<=0,0,IF(ABS((1+$H8)/(1+Parameters!$B$10)-1)<0.000001,1*$G8/(1+Parameters!$B$10),$G8/(1+Parameters!$B$10)*(1-((1+$H8)/(1+Parameters!$B$10))^1)/(1-(1+$H8)/(1+Parameters!$B$10))))+$F8/(1+Parameters!$B$10)^1+IF(1<=0,0,IF(Parameters!$B$10=0,1*$I8*$J8,$I8*$J8*(1-(1/(1+Parameters!$B$10))^1)/Parameters!$B$10))) -> 125000 | AC8: =IF(OR($B8="",2>Parameters!$B$7),"",IF(2<=0,0,IF(ABS((1+$H8)/(1+Parameters!$B$10)-1)<0.000001,2*$G8/(1+Parameters!$B$10),$G8/(1+Parameters!$B$10)*(1-((1+$H8)/(1+Parameters!$B$10))^2)/(1-(1+$H8)/(1+Parameters!$B$10))))+$F8/(1+Parameters!$B$10)^2+IF(2<=0,0,IF(Parameters!$B$10=0,2*$I8*$J8,$I8*$J8*(1-(1/(1+Parameters!$B$10))^2)/Parameters!$B$10))) -> 173439.64 | AD8: =IF(OR($B8="",3>Parameters!$B$7),"",IF(3<=0,0,IF(ABS((1+$H8)/(1+Parameters!$B$10)-1)<0.000001,3*$G8/(1+Parameters!$B$10),$G8/(1+Parameters!$B$10)*(1-((1+$H8)/(1+Parameters!$B$10))^3)/(1-(1+$H8)/(1+Parameters!$B$10))))+$F8/(1+Parameters!$B$10)^3+IF(3<=0,0,IF(Parameters!$B$10=0,3*$I8*$J8,$I8*$J8*(1-(1/(1+Parameters!$B$10))^3)/Parameters!$B$10))) -> 220374.97 | AE8: =IF(OR($B8="",4>Parameters!$B$7),"",IF(4<=0,0,IF(ABS((1+$H8)/(1+Parameters!$B$10)-1)<0.000001,4*$G8/(1+Parameters!$B$10),$G8/(1+Parameters!$B$10)*(1-((1+$H8)/(1+Parameters!$B$10))^4)/(1-(1+$H8)/(1+Parameters!$B$10))))+$F8/(1+Parameters!$B$10)^4+IF(4<=0,0,IF(Parameters!$B$10=0,4*$I8*$J8,$I8*$J8*(1-(1/(1+Parameters!$B$10))^4)/Parameters!$B$10))) -> 265859.54 | AF8: =IF(OR($B8="",5>Parameters!$B$7),"",IF(5<=0,0,IF(ABS((1+$H8)/(1+Parameters!$B$10)-1)<0.000001,5*$G8/(1+Parameters!$B$10),$G8/(1+Parameters!$B$10)*(1-((1+$H8)/(1+Parameters!$B$10))^5)/(1-(1+$H8)/(1+Parameters!$B$10))))+$F8/(1+Parameters!$B$10)^5+IF(5<=0,0,IF(Parameters!$B$10=0,5*$I8*$J8,$I8*$J8*(1-(1/(1+Parameters!$B$10))^5)/Parameters!$B$10))) -> 309944.53 | AG8: =IF(OR($B8="",1>Parameters!$B$7),"",$G8*(1+$H8)^(1-1)) -> 50000 | AH8: =IF(OR($B8="",2>Parameters!$B$7),"",$G8*(1+$H8)^(2-1)) -> 52500 | AI8: =IF(OR($B8="",3>Parameters!$B$7),"",$G8*(1+$H8)^(3-1)) -> 55125 | AJ8: =IF(OR($B8="",4>Parameters!$B$7),"",$G8*(1+$H8)^(4-1)) -> 57881.25 | AK8: =IF(OR($B8="",5>Parameters!$B$7),"",$G8*(1+$H8)^(5-1)) -> 60775.312
A9: DATA-002 | B9: Three different MAU definitions across teams | C9: Data | D9: 8% variance on quarterly board metrics | E9: Open | F9: 120000 | G9: 80000 | H9: 0.05 | I9: 0.01 | J9: 200000 | K9: 60 | M9: =IF($B9="","",$G9+$I9*$J9) -> 82000 | N9: =IF($B9="","",IF(Parameters!$B$7<=0,0,IF(ABS((1+$H9)/(1+Parameters!$B$10)-1)<0.000001,Parameters!$B$7*$G9/(1+Parameters!$B$10),$G9/(1+Parameters!$B$10)*(1-((1+$H9)/(1+Parameters!$B$10))^Parameters!$B$7)/(1-(1+$H9)/(1+Parameters!$B$10))))+IF(Parameters!$B$7<=0,0,IF(Parameters!$B$10=0,Parameters!$B$7*$I9*$J9,$I9*$J9*(1-(1/(1+Parameters!$B$10))^Parameters!$B$7)/Parameters!$B$10))) -> 358343.32 | O9: =IF(OR($B9="",1>Parameters!$B$7),"",$N9-AB9) -> 171306.29 | P9: =IF(OR($B9="",2>Parameters!$B$7),"",$N9-AC9) -> 105805.6 | Q9: =IF(OR($B9="",3>Parameters!$B$7),"",$N9-AD9) -> 41822.722 | R9: =IF(OR($B9="",4>Parameters!$B$7),"",$N9-AE9) -> -20662.166 | S9: =IF(OR($B9="",5>Parameters!$B$7),"",$N9-AF9) -> -81669.984 | T9: =IF($B9="","",IF(MAX($O9:$S9)<0,"Accept",MATCH(MAX($O9:$S9),$O9:$S9,0))) -> 1 | U9: =IF($B9="","",MAX($O9:$S9)) -> 171306.29 | V9: =IF($B9="","",IF($F9>0,ROUND($O9/$F9,2),IF(N($O9)>0,Lists!$F$2,0))+IF($W9="Yes",Lists!$I$2,0)) -> 1.43 | W9: =IF($B9="","",IF(COUNTIFS($L$2:$L$41,$A9,$E$2:$E$41,"Open",$A$2:$A$41,"<>"&$A9)>0,"Yes","No")) -> No | X9: =IF($B9="","",IF($V9>=Lists!$F$2,"High",IF($V9>=Lists!$F$3,"Medium","Low"))) -> Medium | Y9: =IF(OR($B9="",$E9<>"Open"),"",IF($L9="",(INDEX(Lists!$G$2:$G$4,MATCH($X9,Lists!$E$2:$E$4,0))*1000000000000-$U9-$H9),IFERROR(MAX((INDEX(Lists!$G$2:$G$4,MATCH($X9,Lists!$E$2:$E$4,0))*1000000000000-$U9-$H9),INDEX($Y$2:$Y$41,MATCH($L9,$A$2:$A$41,0))+1),(INDEX(Lists!$G$2:$G$4,MATCH($X9,Lists!$E$2:$E$4,0))*1000000000000-$U9-$H9)))) -> 1.9999998e+12 | Z9: =IF($Y9="","",RANK($Y9,$Y$2:$Y$41,1)+COUNTIF($Y$2:$Y9,$Y9)-1) -> 9 | AA9: ="" | AB9: =IF(OR($B9="",1>Parameters!$B$7),"",IF(1<=0,0,IF(ABS((1+$H9)/(1+Parameters!$B$10)-1)<0.000001,1*$G9/(1+Parameters!$B$10),$G9/(1+Parameters!$B$10)*(1-((1+$H9)/(1+Parameters!$B$10))^1)/(1-(1+$H9)/(1+Parameters!$B$10))))+$F9/(1+Parameters!$B$10)^1+IF(1<=0,0,IF(Parameters!$B$10=0,1*$I9*$J9,$I9*$J9*(1-(1/(1+Parameters!$B$10))^1)/Parameters!$B$10))) -> 187037.04 | AC9: =IF(OR($B9="",2>Parameters!$B$7),"",IF(2<=0,0,IF(ABS((1+$H9)/(1+Parameters!$B$10)-1)<0.000001,2*$G9/(1+Parameters!$B$10),$G9/(1+Parameters!$B$10)*(1-((1+$H9)/(1+Parameters!$B$10))^2)/(1-(1+$H9)/(1+Parameters!$B$10))))+$F9/(1+Parameters!$B$10)^2+IF(2<=0,0,IF(Parameters!$B$10=0,2*$I9*$J9,$I9*$J9*(1-(1/(1+Parameters!$B$10))^2)/Parameters!$B$10))) -> 252537.72 | AD9: =IF(OR($B9="",3>Parameters!$B$7),"",IF(3<=0,0,IF(ABS((1+$H9)/(1+Parameters!$B$10)-1)<0.000001,3*$G9/(1+Parameters!$B$10),$G9/(1+Parameters!$B$10)*(1-((1+$H9)/(1+Parameters!$B$10))^3)/(1-(1+$H9)/(1+Parameters!$B$10))))+$F9/(1+Parameters!$B$10)^3+IF(3<=0,0,IF(Parameters!$B$10=0,3*$I9*$J9,$I9*$J9*(1-(1/(1+Parameters!$B$10))^3)/Parameters!$B$10))) -> 316520.6 | AE9: =IF(OR($B9="",4>Parameters!$B$7),"",IF(4<=0,0,IF(ABS((1+$H9)/(1+Parameters!$B$10)-1)<0.000001,4*$G9/(1+Parameters!$B$10),$G9/(1+Parameters!$B$10)*(1-((1+$H9)/(1+Parameters!$B$10))^4)/(1-(1+$H9)/(1+Parameters!$B$10))))+$F9/(1+Parameters!$B$10)^4+IF(4<=0,0,IF(Parameters!$B$10=0,4*$I9*$J9,$I9*$J9*(1-(1/(1+Parameters!$B$10))^4)/Parameters!$B$10))) -> 379005.49 | AF9: =IF(OR($B9="",5>Parameters!$B$7),"",IF(5<=0,0,IF(ABS((1+$H9)/(1+Parameters!$B$10)-1)<0.000001,5*$G9/(1+Parameters!$B$10),$G9/(1+Parameters!$B$10)*(1-((1+$H9)/(1+Parameters!$B$10))^5)/(1-(1+$H9)/(1+Parameters!$B$10))))+$F9/(1+Parameters!$B$10)^5+IF(5<=0,0,IF(Parameters!$B$10=0,5*$I9*$J9,$I9*$J9*(1-(1/(1+Parameters!$B$10))^5)/Parameters!$B$10))) -> 440013.31 | AG9: =IF(OR($B9="",1>Parameters!$B$7),"",$G9*(1+$H9)^(1-1)) -> 80000 | AH9: =IF(OR($B9="",2>Parameters!$B$7),"",$G9*(1+$H9)^(2-1)) -> 84000 | AI9: =IF(OR($B9="",3>Parameters!$B$7),"",$G9*(1+$H9)^(3-1)) -> 88200 | AJ9: =IF(OR($B9="",4>Parameters!$B$7),"",$G9*(1+$H9)^(4-1)) -> 92610 | AK9: =IF(OR($B9="",5>Parameters!$B$7),"",$G9*(1+$H9)^(5-1)) -> 97240.5
A10: ARCH-002 | B10: PostgreSQL 11 EOL - upgrade required | C10: Infrastructure | D10: EOL since 2023, security and support exposure growing fast | E10: Open | F10: 200000 | G10: 50000 | H10: 0.3 | I10: 0.05 | J10: 1500000 | K10: 90 | M10: =IF($B10="","",$G10+$I10*$J10) -> 125000 | N10: =IF($B10="","",IF(Parameters!$B$7<=0,0,IF(ABS((1+$H10)/(1+Parameters!$B$10)-1)<0.000001,Parameters!$B$7*$G10/(1+Parameters!$B$10),$G10/(1+Parameters!$B$10)*(1-((1+$H10)/(1+Parameters!$B$10))^Parameters!$B$7)/(1-(1+$H10)/(1+Parameters!$B$10))))+IF(Parameters!$B$7<=0,0,IF(Parameters!$B$10=0,Parameters!$B$7*$I10*$J10,$I10*$J10*(1-(1/(1+Parameters!$B$10))^Parameters!$B$7)/Parameters!$B$10))) -> 646489.11 | O10: =IF(OR($B10="",1>Parameters!$B$7),"",$N10-AB10) -> 345563.18 | P10: =IF(OR($B10="",2>Parameters!$B$7),"",$N10-AC10) -> 239253.17 | Q10: =IF(OR($B10="",3>Parameters!$B$7),"",$N10-AD10) -> 125338.24 | R10: =IF(OR($B10="",4>Parameters!$B$7),"",$N10-AE10) -> 1228.4527 | S10: =IF(OR($B10="",5>Parameters!$B$7),"",$N10-AF10) -> -136116.64 | T10: =IF($B10="","",IF(MAX($O10:$S10)<0,"Accept",MATCH(MAX($O10:$S10),$O10:$S10,0))) -> 1 | U10: =IF($B10="","",MAX($O10:$S10)) -> 345563.18 | V10: =IF($B10="","",IF($F10>0,ROUND($O10/$F10,2),IF(N($O10)>0,Lists!$F$2,0))+IF($W10="Yes",Lists!$I$2,0)) -> 1.73 | W10: =IF($B10="","",IF(COUNTIFS($L$2:$L$41,$A10,$E$2:$E$41,"Open",$A$2:$A$41,"<>"&$A10)>0,"Yes","No")) -> No | X10: =IF($B10="","",IF($V10>=Lists!$F$2,"High",IF($V10>=Lists!$F$3,"Medium","Low"))) -> Medium | Y10: =IF(OR($B10="",$E10<>"Open"),"",IF($L10="",(INDEX(Lists!$G$2:$G$4,MATCH($X10,Lists!$E$2:$E$4,0))*1000000000000-$U10-$H10),IFERROR(MAX((INDEX(Lists!$G$2:$G$4,MATCH($X10,Lists!$E$2:$E$4,0))*1000000000000-$U10-$H10),INDEX($Y$2:$Y$41,MATCH($L10,$A$2:$A$41,0))+1),(INDEX(Lists!$G$2:$G$4,MATCH($X10,Lists!$E$2:$E$4,0))*1000000000000-$U10-$H10)))) -> 1.9999997e+12 | Z10: =IF($Y10="","",RANK($Y10,$Y$2:$Y$41,1)+COUNTIF($Y$2:$Y10,$Y10)-1) -> 8 | AA10: ="" | AB10: =IF(OR($B10="",1>Parameters!$B$7),"",IF(1<=0,0,IF(ABS((1+$H10)/(1+Parameters!$B$10)-1)<0.000001,1*$G10/(1+Parameters!$B$10),$G10/(1+Parameters!$B$10)*(1-((1+$H10)/(1+Parameters!$B$10))^1)/(1-(1+$H10)/(1+Parameters!$B$10))))+$F10/(1+Parameters!$B$10)^1+IF(1<=0,0,IF(Parameters!$B$10=0,1*$I10*$J10,$I10*$J10*(1-(1/(1+Parameters!$B$10))^1)/Parameters!$B$10))) -> 300925.93 | AC10: =IF(OR($B10="",2>Parameters!$B$7),"",IF(2<=0,0,IF(ABS((1+$H10)/(1+Parameters!$B$10)-1)<0.000001,2*$G10/(1+Parameters!$B$10),$G10/(1+Parameters!$B$10)*(1-((1+$H10)/(1+Parameters!$B$10))^2)/(1-(1+$H10)/(1+Parameters!$B$10))))+$F10/(1+Parameters!$B$10)^2+IF(2<=0,0,IF(Parameters!$B$10=0,2*$I10*$J10,$I10*$J10*(1-(1/(1+Parameters!$B$10))^2)/Parameters!$B$10))) -> 407235.94 | AD10: =IF(OR($B10="",3>Parameters!$B$7),"",IF(3<=0,0,IF(ABS((1+$H10)/(1+Parameters!$B$10)-1)<0.000001,3*$G10/(1+Parameters!$B$10),$G10/(1+Parameters!$B$10)*(1-((1+$H10)/(1+Parameters!$B$10))^3)/(1-(1+$H10)/(1+Parameters!$B$10))))+$F10/(1+Parameters!$B$10)^3+IF(3<=0,0,IF(Parameters!$B$10=0,3*$I10*$J10,$I10*$J10*(1-(1/(1+Parameters!$B$10))^3)/Parameters!$B$10))) -> 521150.87 | AE10: =IF(OR($B10="",4>Parameters!$B$7),"",IF(4<=0,0,IF(ABS((1+$H10)/(1+Parameters!$B$10)-1)<0.000001,4*$G10/(1+Parameters!$B$10),$G10/(1+Parameters!$B$10)*(1-((1+$H10)/(1+Parameters!$B$10))^4)/(1-(1+$H10)/(1+Parameters!$B$10))))+$F10/(1+Parameters!$B$10)^4+IF(4<=0,0,IF(Parameters!$B$10=0,4*$I10*$J10,$I10*$J10*(1-(1/(1+Parameters!$B$10))^4)/Parameters!$B$10))) -> 645260.66 | AF10: =IF(OR($B10="",5>Parameters!$B$7),"",IF(5<=0,0,IF(ABS((1+$H10)/(1+Parameters!$B$10)-1)<0.000001,5*$G10/(1+Parameters!$B$10),$G10/(1+Parameters!$B$10)*(1-((1+$H10)/(1+Parameters!$B$10))^5)/(1-(1+$H10)/(1+Parameters!$B$10))))+$F10/(1+Parameters!$B$10)^5+IF(5<=0,0,IF(Parameters!$B$10=0,5*$I10*$J10,$I10*$J10*(1-(1/(1+Parameters!$B$10))^5)/Parameters!$B$10))) -> 782605.75 | AG10: =IF(OR($B10="",1>Parameters!$B$7),"",$G10*(1+$H10)^(1-1)) -> 50000 | AH10: =IF(OR($B10="",2>Parameters!$B$7),"",$G10*(1+$H10)^(2-1)) -> 65000 | AI10: =IF(OR($B10="",3>Parameters!$B$7),"",$G10*(1+$H10)^(3-1)) -> 84500 | AJ10: =IF(OR($B10="",4>Parameters!$B$7),"",$G10*(1+$H10)^(4-1)) -> 109850 | AK10: =IF(OR($B10="",5>Parameters!$B$7),"",$G10*(1+$H10)^(5-1)) -> 142805
A11: IP-001 | B11: Missing IP assignments for 12 engineers | C11: Process | D11: Pre-close cleanup required, low effort high reward | E11: Open | F11: 50000 | G11: 25000 | H11: 0.05 | I11: 0.1 | J11: 5000000 | K11: 20 | M11: =IF($B11="","",$G11+$I11*$J11) -> 525000 | N11: =IF($B11="","",IF(Parameters!$B$7<=0,0,IF(ABS((1+$H11)/(1+Parameters!$B$10)-1)<0.000001,Parameters!$B$7*$G11/(1+Parameters!$B$10),$G11/(1+Parameters!$B$10)*(1-((1+$H11)/(1+Parameters!$B$10))^Parameters!$B$7)/(1-(1+$H11)/(1+Parameters!$B$10))))+IF(Parameters!$B$7<=0,0,IF(Parameters!$B$10=0,Parameters!$B$7*$I11*$J11,$I11*$J11*(1-(1/(1+Parameters!$B$10))^Parameters!$B$7)/Parameters!$B$10))) -> 2105841.9 | O11: =IF(OR($B11="",1>Parameters!$B$7),"",$N11-AB11) -> 1573434.5 | P11: =IF(OR($B11="",2>Parameters!$B$7),"",$N11-AC11) -> 1125689.3 | Q11: =IF(OR($B11="",3>Parameters!$B$7),"",$N11-AD11) -> 710068.46 | R11: =IF(OR($B11="",4>Parameters!$B$7),"",$N11-AE11) -> 324221.43 | S11: =IF(OR($B11="",5>Parameters!$B$7),"",$N11-AF11) -> -34029.16 | T11: =IF($B11="","",IF(MAX($O11:$S11)<0,"Accept",MATCH(MAX($O11:$S11),$O11:$S11,0))) -> 1 | U11: =IF($B11="","",MAX($O11:$S11)) -> 1573434.5 | V11: =IF($B11="","",IF($F11>0,ROUND($O11/$F11,2),IF(N($O11)>0,Lists!$F$2,0))+IF($W11="Yes",Lists!$I$2,0)) -> 31.47 | W11: =IF($B11="","",IF(COUNTIFS($L$2:$L$41,$A11,$E$2:$E$41,"Open",$A$2:$A$41,"<>"&$A11)>0,"Yes","No")) -> No | X11: =IF($B11="","",IF($V11>=Lists!$F$2,"High",IF($V11>=Lists!$F$3,"Medium","Low"))) -> High | Y11: =IF(OR($B11="",$E11<>"Open"),"",IF($L11="",(INDEX(Lists!$G$2:$G$4,MATCH($X11,Lists!$E$2:$E$4,0))*1000000000000-$U11-$H11),IFERROR(MAX((INDEX(Lists!$G$2:$G$4,MATCH($X11,Lists!$E$2:$E$4,0))*1000000000000-$U11-$H11),INDEX($Y$2:$Y$41,MATCH($L11,$A$2:$A$41,0))+1),(INDEX(Lists!$G$2:$G$4,MATCH($X11,Lists!$E$2:$E$4,0))*1000000000000-$U11-$H11)))) -> 9.9999843e+11 | Z11: =IF($Y11="","",RANK($Y11,$Y$2:$Y$41,1)+COUNTIF($Y$2:$Y11,$Y11)-1) -> 4 | AA11: ="" | AB11: =IF(OR($B11="",1>Parameters!$B$7),"",IF(1<=0,0,IF(ABS((1+$H11)/(1+Parameters!$B$10)-1)<0.000001,1*$G11/(1+Parameters!$B$10),$G11/(1+Parameters!$B$10)*(1-((1+$H11)/(1+Parameters!$B$10))^1)/(1-(1+$H11)/(1+Parameters!$B$10))))+$F11/(1+Parameters!$B$10)^1+IF(1<=0,0,IF(Parameters!$B$10=0,1*$I11*$J11,$I11*$J11*(1-(1/(1+Parameters!$B$10))^1)/Parameters!$B$10))) -> 532407.41 | AC11: =IF(OR($B11="",2>Parameters!$B$7),"",IF(2<=0,0,IF(ABS((1+$H11)/(1+Parameters!$B$10)-1)<0.000001,2*$G11/(1+Parameters!$B$10),$G11/(1+Parameters!$B$10)*(1-((1+$H11)/(1+Parameters!$B$10))^2)/(1-(1+$H11)/(1+Parameters!$B$10))))+$F11/(1+Parameters!$B$10)^2+IF(2<=0,0,IF(Parameters!$B$10=0,2*$I11*$J11,$I11*$J11*(1-(1/(1+Parameters!$B$10))^2)/Parameters!$B$10))) -> 980152.61 | AD11: =IF(OR($B11="",3>Parameters!$B$7),"",IF(3<=0,0,IF(ABS((1+$H11)/(1+Parameters!$B$10)-1)<0.000001,3*$G11/(1+Parameters!$B$10),$G11/(1+Parameters!$B$10)*(1-((1+$H11)/(1+Parameters!$B$10))^3)/(1-(1+$H11)/(1+Parameters!$B$10))))+$F11/(1+Parameters!$B$10)^3+IF(3<=0,0,IF(Parameters!$B$10=0,3*$I11*$J11,$I11*$J11*(1-(1/(1+Parameters!$B$10))^3)/Parameters!$B$10))) -> 1395773.4 | AE11: =IF(OR($B11="",4>Parameters!$B$7),"",IF(4<=0,0,IF(ABS((1+$H11)/(1+Parameters!$B$10)-1)<0.000001,4*$G11/(1+Parameters!$B$10),$G11/(1+Parameters!$B$10)*(1-((1+$H11)/(1+Parameters!$B$10))^4)/(1-(1+$H11)/(1+Parameters!$B$10))))+$F11/(1+Parameters!$B$10)^4+IF(4<=0,0,IF(Parameters!$B$10=0,4*$I11*$J11,$I11*$J11*(1-(1/(1+Parameters!$B$10))^4)/Parameters!$B$10))) -> 1781620.4 | AF11: =IF(OR($B11="",5>Parameters!$B$7),"",IF(5<=0,0,IF(ABS((1+$H11)/(1+Parameters!$B$10)-1)<0.000001,5*$G11/(1+Parameters!$B$10),$G11/(1+Parameters!$B$10)*(1-((1+$H11)/(1+Parameters!$B$10))^5)/(1-(1+$H11)/(1+Parameters!$B$10))))+$F11/(1+Parameters!$B$10)^5+IF(5<=0,0,IF(Parameters!$B$10=0,5*$I11*$J11,$I11*$J11*(1-(1/(1+Parameters!$B$10))^5)/Parameters!$B$10))) -> 2139871 | AG11: =IF(OR($B11="",1>Parameters!$B$7),"",$G11*(1+$H11)^(1-1)) -> 25000 | AH11: =IF(OR($B11="",2>Parameters!$B$7),"",$G11*(1+$H11)^(2-1)) -> 26250 | AI11: =IF(OR($B11="",3>Parameters!$B$7),"",$G11*(1+$H11)^(3-1)) -> 27562.5 | AJ11: =IF(OR($B11="",4>Parameters!$B$7),"",$G11*(1+$H11)^(4-1)) -> 28940.625 | AK11: =IF(OR($B11="",5>Parameters!$B$7),"",$G11*(1+$H11)^(5-1)) -> 30387.656
A12: ARCH-003 | B12: Code modernization to support multi-tenancy | C12: Code | D12: Application code refactoring blocked until multi-tenancy infra exists | E12: Open | F12: 800000 | G12: 150000 | H12: 0.1 | I12: 0.03 | J12: 1000000 | K12: 240 | L12: ARCH-001 | M12: =IF($B12="","",$G12+$I12*$J12) -> 180000 | N12: =IF($B12="","",IF(Parameters!$B$7<=0,0,IF(ABS((1+$H12)/(1+Parameters!$B$10)-1)<0.000001,Parameters!$B$7*$G12/(1+Parameters!$B$10),$G12/(1+Parameters!$B$10)*(1-((1+$H12)/(1+Parameters!$B$10))^Parameters!$B$7)/(1-(1+$H12)/(1+Parameters!$B$10))))+IF(Parameters!$B$7<=0,0,IF(Parameters!$B$10=0,Parameters!$B$7*$I12*$J12,$I12*$J12*(1-(1/(1+Parameters!$B$10))^Parameters!$B$7)/Parameters!$B$10))) -> 840426.64 | O12: =IF(OR($B12="",1>Parameters!$B$7),"",$N12-AB12) -> -66980.771 | P12: =IF(OR($B12="",2>Parameters!$B$7),"",$N12-AC12) -> -179292.16 | Q12: =IF(OR($B12="",3>Parameters!$B$7),"",$N12-AD12) -> -296382.41 | R12: =IF(OR($B12="",4>Parameters!$B$7),"",$N12-AE12) -> -418140.11 | S12: =IF(OR($B12="",5>Parameters!$B$7),"",$N12-AF12) -> -544466.56 | T12: =IF($B12="","",IF(MAX($O12:$S12)<0,"Accept",MATCH(MAX($O12:$S12),$O12:$S12,0))) -> Accept | U12: =IF($B12="","",MAX($O12:$S12)) -> -66980.771 | V12: =IF($B12="","",IF($F12>0,ROUND($O12/$F12,2),IF(N($O12)>0,Lists!$F$2,0))+IF($W12="Yes",Lists!$I$2,0)) -> -0.08 | W12: =IF($B12="","",IF(COUNTIFS($L$2:$L$41,$A12,$E$2:$E$41,"Open",$A$2:$A$41,"<>"&$A12)>0,"Yes","No")) -> No | X12: =IF($B12="","",IF($V12>=Lists!$F$2,"High",IF($V12>=Lists!$F$3,"Medium","Low"))) -> Low | Y12: =IF(OR($B12="",$E12<>"Open"),"",IF($L12="",(INDEX(Lists!$G$2:$G$4,MATCH($X12,Lists!$E$2:$E$4,0))*1000000000000-$U12-$H12),IFERROR(MAX((INDEX(Lists!$G$2:$G$4,MATCH($X12,Lists!$E$2:$E$4,0))*1000000000000-$U12-$H12),INDEX($Y$2:$Y$41,MATCH($L12,$A$2:$A$41,0))+1),(INDEX(Lists!$G$2:$G$4,MATCH($X12,Lists!$E$2:$E$4,0))*1000000000000-$U12-$H12)))) -> 3.0000001e+12 | Z12: =IF($Y12="","",RANK($Y12,$Y$2:$Y$41,1)+COUNTIF($Y$2:$Y12,$Y12)-1) -> 12 | AA12: ="" | AB12: =IF(OR($B12="",1>Parameters!$B$7),"",IF(1<=0,0,IF(ABS((1+$H12)/(1+Parameters!$B$10)-1)<0.000001,1*$G12/(1+Parameters!$B$10),$G12/(1+Parameters!$B$10)*(1-((1+$H12)/(1+Parameters!$B$10))^1)/(1-(1+$H12)/(1+Parameters!$B$10))))+$F12/(1+Parameters!$B$10)^1+IF(1<=0,0,IF(Parameters!$B$10=0,1*$I12*$J12,$I12*$J12*(1-(1/(1+Parameters!$B$10))^1)/Parameters!$B$10))) -> 907407.41 | AC12: =IF(OR($B12="",2>Parameters!$B$7),"",IF(2<=0,0,IF(ABS((1+$H12)/(1+Parameters!$B$10)-1)<0.000001,2*$G12/(1+Parameters!$B$10),$G12/(1+Parameters!$B$10)*(1-((1+$H12)/(1+Parameters!$B$10))^2)/(1-(1+$H12)/(1+Parameters!$B$10))))+$F12/(1+Parameters!$B$10)^2+IF(2<=0,0,IF(Parameters!$B$10=0,2*$I12*$J12,$I12*$J12*(1-(1/(1+Parameters!$B$10))^2)/Parameters!$B$10))) -> 1019718.8 | AD12: =IF(OR($B12="",3>Parameters!$B$7),"",IF(3<=0,0,IF(ABS((1+$H12)/(1+Parameters!$B$10)-1)<0.000001,3*$G12/(1+Parameters!$B$10),$G12/(1+Parameters!$B$10)*(1-((1+$H12)/(1+Parameters!$B$10))^3)/(1-(1+$H12)/(1+Parameters!$B$10))))+$F12/(1+Parameters!$B$10)^3+IF(3<=0,0,IF(Parameters!$B$10=0,3*$I12*$J12,$I12*$J12*(1-(1/(1+Parameters!$B$10))^3)/Parameters!$B$10))) -> 1136809 | AE12: =IF(OR($B12="",4>Parameters!$B$7),"",IF(4<=0,0,IF(ABS((1+$H12)/(1+Parameters!$B$10)-1)<0.000001,4*$G12/(1+Parameters!$B$10),$G12/(1+Parameters!$B$10)*(1-((1+$H12)/(1+Parameters!$B$10))^4)/(1-(1+$H12)/(1+Parameters!$B$10))))+$F12/(1+Parameters!$B$10)^4+IF(4<=0,0,IF(Parameters!$B$10=0,4*$I12*$J12,$I12*$J12*(1-(1/(1+Parameters!$B$10))^4)/Parameters!$B$10))) -> 1258566.7 | AF12: =IF(OR($B12="",5>Parameters!$B$7),"",IF(5<=0,0,IF(ABS((1+$H12)/(1+Parameters!$B$10)-1)<0.000001,5*$G12/(1+Parameters!$B$10),$G12/(1+Parameters!$B$10)*(1-((1+$H12)/(1+Parameters!$B$10))^5)/(1-(1+$H12)/(1+Parameters!$B$10))))+$F12/(1+Parameters!$B$10)^5+IF(5<=0,0,IF(Parameters!$B$10=0,5*$I12*$J12,$I12*$J12*(1-(1/(1+Parameters!$B$10))^5)/Parameters!$B$10))) -> 1384893.2 | AG12: =IF(OR($B12="",1>Parameters!$B$7),"",$G12*(1+$H12)^(1-1)) -> 150000 | AH12: =IF(OR($B12="",2>Parameters!$B$7),"",$G12*(1+$H12)^(2-1)) -> 165000 | AI12: =IF(OR($B12="",3>Parameters!$B$7),"",$G12*(1+$H12)^(3-1)) -> 181500 | AJ12: =IF(OR($B12="",4>Parameters!$B$7),"",$G12*(1+$H12)^(4-1)) -> 199650 | AK12: =IF(OR($B12="",5>Parameters!$B$7),"",$G12*(1+$H12)^(5-1)) -> 219615
